Workbook

Sheet Config
A1: DINSIDES — Cierre Comercial | Periodo mensual ---
A3: Periodo de análisis
A4: Periodo_mes | B4: 46023 | D4: Moneda | E4: Soles (S/)
A5: Inicio (incluye) | B5: 46023
A6: Fin (incluye) | B6: 46053
A7: Código periodo (Mes 1) | B7: 46023
A8: Pago moto por recojo (S/) | B8: 4
A9: Mes 2 (periodo) | B9: 46054
A10: Mes 3 (periodo) | B10: 46082

Sheet Resumen Mensual
A1: Resumen Periodo
K2: Distrito | L2: Frecuencia (Tiendas)
A3: KPIs del periodo | K3: Santiago de Surco | L3: =COUNTIF(Tiendas!$N$4:$N$176,$K3) -> 6
A4: Periodo | B4: 46023 | E4: ENVIOS TOTALES | F4: =COUNTIF('DATA ENVIOS'!$A$4:$A$2100,B4) -> 988 | K4: San Juan de Miraflores | L4: =COUNTIF(Tiendas!$N$4:$N$176,$K4) -> 6
A5: TIENDAS REGISTRADAS | B5: =COUNTIF(Tiendas!$J$4:$J$176,"Sí") -> 75 | E5: PROMEDIO T. E. | F5: =F4/B5 -> 13.173333 | K5: San Martín de Porres | L5: =COUNTIF(Tiendas!$N$4:$N$176,$K5) -> 5
A6: LEADS GANADOS | B6: =COUNTIF(Tiendas!$L$4:$L$176,">0") -> 75 | K6: El Agustino | L6: =COUNTIF(Tiendas!$N$4:$N$176,$K6) -> 4
K7: La Victoria | L7: =COUNTIF(Tiendas!$N$4:$N$176,$K7) -> 4
A8: Ingreso total operativo (S/) | B8: =SUMIFS('DATA ENVIOS'!$H$4:$H$2000,'DATA ENVIOS'!$A$4:$A$2000,Config!$B$4)+SUMIFS('DATA RECOJOS'!$G$4:$G$201,'DATA RECOJOS'!$A$4:$A$201,Config!$B$4)+B14 -> 9710.0339 | K8: Ate | L8: =COUNTIF(Tiendas!$N$4:$N$176,$K8) -> 4
A9: Costo total operativo (S/) | B9: =SUMIFS('DATA ENVIOS'!$I$4:$I$2000,'DATA ENVIOS'!$A$4:$A$2000,Config!$B$4)+SUMIFS('DATA RECOJOS'!$H$4:$H$201,'DATA RECOJOS'!$A$4:$A$201,Config!$B$4)+SUMIFS('DATA APLICATIVOS'!$F$4:$F$203,'DATA APLICATIVOS'!$A$4:$A$203,Config!$B$4) -> 5438.5 | K9: BREÑA | L9: =COUNTIF(Tiendas!$N$4:$N$176,$K9) -> 3
A10: Margen total operativo (S/) | B10: =B8-B9 -> 4271.5339 | K10: Cercado de Lima | L10: =COUNTIF(Tiendas!$N$4:$N$176,$K10) -> 3
A11: Ticket promedio del mes (S/Envios) | B11: =IFERROR(SUMIFS('DATA ENVIOS'!$H$4:$H$2000,'DATA ENVIOS'!$A$4:$A$2000,Config!$B$4)/COUNTIFS('DATA ENVIOS'!$A$4:$A$2000,Config!$B$4,'DATA ENVIOS'!$H$4:$H$2000,">0"),0) -> 9.4897888 | K11: San Juan de Lurigancho | L11: =COUNTIF(Tiendas!$N$4:$N$176,$K11) -> 4
A12: Costo operativo por lead ganado (S/) | B12: =IF(B5=0,"",B9/B5) -> 72.513333 | K12: Chorrillos | L12: =COUNTIF(Tiendas!$N$4:$N$176,$K12) -> 3
A13: Ingreso por lead ganado (S/) | B13: =IF(B5=0,"",B8/B5) -> 129.46712 | K13: Los Olivos | L13: =COUNTIF(Tiendas!$N$4:$N$176,$K13) -> 3
A14: Ingreso anulados fulfillment (S/) | B14: =SUM(Tiendas!$R$4:$R$176) -> 112 | K14: San Borja | L14: =COUNTIF(Tiendas!$N$4:$N$176,$K14) -> 2
A15: Recojos — conteo clave | K15: San Isidro | L15: =COUNTIF(Tiendas!$N$4:$N$176,$K15) -> 2
A16: Recojos cobrados (veces) | B16: =SUMIFS('DATA RECOJOS'!$D$4:$D$201,'DATA RECOJOS'!$A$4:$A$201,Config!$B$4,'DATA RECOJOS'!$C$4:$C$201,"1 pedido (cobra S/8)") -> 42 | K16: Surquillo | L16: =COUNTIF(Tiendas!$N$4:$N$176,$K16) -> 2
A17: Recojos gratis (veces) | B17: =SUMIFS('DATA RECOJOS'!$D$4:$D$201,'DATA RECOJOS'!$A$4:$A$201,Config!$B$4,'DATA RECOJOS'!$C$4:$C$201,"2+ entregados (gratis)") -> 109 | K17: Carabayllo | L17: =COUNTIF(Tiendas!$N$4:$N$176,$K17) -> 2
A18: Pago total al motorizado por recojos (S/) | B18: =SUMIFS('DATA RECOJOS'!$H$4:$H$201,'DATA RECOJOS'!$A$4:$A$201,Config!$B$4) -> 608 | K18: Comas | L18: =COUNTIF(Tiendas!$N$4:$N$176,$K18) -> 2
K19: Puente Piedra | L19: =COUNTIF(Tiendas!$N$4:$N$176,$K19) -> 2
A20: Vendedores — comisiones | K20: Ventanilla | L20: =COUNTIF(Tiendas!$N$4:$N$176,$K20) -> 2
A21: Comisión total vendedores (S/) | B21: =SUM('COMISIONES Y LEADS'!$E$14:$E$18) -> 232.8 | K21: Villa María del Triunfo | L21: =COUNTIF(Tiendas!$N$4:$N$176,$K21) -> 2
A22: Costo total + comisión (S/) | B22: =B9+B21 -> 5671.3 | K22: Barranco | L22: =COUNTIF(Tiendas!$N$4:$N$176,$K22) -> 1
A23: Margen - comisión (S/) | B23: =B8-B22 -> 4038.7339 | K23: Jesús María | L23: =COUNTIF(Tiendas!$N$4:$N$176,$K23) -> 1
A24: Costo por lead ganado + comisión (S/) | B24: =IF(B5=0,"",B22/B5) -> 75.617333 | K24: La Molina | L24: =COUNTIF(Tiendas!$N$4:$N$176,$K24) -> 1
K25: Magdalena del Mar | L25: =COUNTIF(Tiendas!$N$4:$N$176,$K25) -> 1
A26: Distrito lead ganado más frecuente | B26: {=IFERROR(INDEX($K$3:$K$64,MATCH(MAX($L$3:$L$64),$L$3:$L$64,0)),"-")} -> Santiago de Surco | K26: Pueblo Libre | L26: =COUNTIF(Tiendas!$N$4:$N$176,$K26) -> 1
K27: Rímac | L27: =COUNTIF(Tiendas!$N$4:$N$176,$K27) -> 1
K28: San Luis | L28: =COUNTIF(Tiendas!$N$4:$N$176,$K28) -> 1
K29: San Miguel | L29: =COUNTIF(Tiendas!$N$4:$N$176,$K29) -> 1
K30: Santa Anita | L30: =COUNTIF(Tiendas!$N$4:$N$176,$K30) -> 1
K31: Callao | L31: =COUNTIF(Tiendas!$N$4:$N$176,$K31) -> 1
K32: Carmen de la Legua Reynoso | L32: =COUNTIF(Tiendas!$N$4:$N$176,$K32) -> 1
K33: Villa El Salvador | L33: =COUNTIF(Tiendas!$N$4:$N$176,$K33) -> 1
K34: Lurin | L34: =COUNTIF(Tiendas!$N$4:$N$176,$K34) -> 1
K35: Lince | L35: =COUNTIF(Tiendas!$N$4:$N$176,$K35) -> 0
K36: Miraflores | L36: =COUNTIF(Tiendas!$N$4:$N$176,$K36) -> 0
K37: Salamanca Ate | L37: =COUNTIF(Tiendas!$N$4:$N$176,$K37) -> 0
K38: Bellavista | L38: =COUNTIF(Tiendas!$N$4:$N$176,$K38) -> 0
... K64: Pucusana | L64: =COUNTIF(Tiendas!$N$4:$N$176,$K64) -> 0

Sheet INFO VENDEDOR
A1: Vista_Vendedor — resumen comercial y operativo (mensual)
A3: Nombre de vendedor: | B3: jordan
A5: Nivel de vendedor: | B5: =IFERROR(VLOOKUP($B$3,'COMISIONES Y LEADS'!$A$14:$C$18,3,FALSE),"-") -> Pacha Mama
A6: Envíos del periodo (Entregados): | B6: =IFERROR(VLOOKUP($B$3,'COMISIONES Y LEADS'!$A$14:$B$18,2,FALSE),"") -> 388
A7: Comisión por envío (S/): | B7: =IFERROR(VLOOKUP($B$3,'COMISIONES Y LEADS'!$A$14:$D$18,4,FALSE),0) -> 0.6
A8: Comisión total (S/): | B8: =IFERROR(VLOOKUP($B$3,'COMISIONES Y LEADS'!$A$14:$E$18,5,FALSE),0) -> 232.8
A10: Leads — gestión y conversiones | E10: Finanzas — envíos + recojos
A11: Leads entrantes: | B11: =IFERROR(VLOOKUP($B$3,'COMISIONES Y LEADS'!$A$14:$H$18,7,FALSE),0) -> 190 | E11: Ingreso total (S/): | F11: =SUMIFS('DATA ENVIOS'!$H$4:$H$2000,'DATA ENVIOS'!$K$4:$K$2000,$B$3,'DATA ENVIOS'!$A$4:$A$2000,Config!$B$4)+SUMIFS('DATA RECOJOS'!$G$4:$G$201,'DATA RECOJOS'!$J$4:$J$201,$B$3,'DATA RECOJOS'!$A$4:$A$201,Config!$B$4) -> 3856.9492
A12: Leads orgánicos: | B12: =IFERROR(VLOOKUP($B$3,'COMISIONES Y LEADS'!$A$14:$H$18,8,FALSE),0) -> 156 | E12: Costo moto total (S/): | F12: =SUMIFS('DATA ENVIOS'!$I$4:$I$2000,'DATA ENVIOS'!$K$4:$K$2000,$B$3,'DATA ENVIOS'!$A$4:$A$2000,Config!$B$4)+SUMIFS('DATA RECOJOS'!$H$4:$H$201,'DATA RECOJOS'!$J$4:$J$201,$B$3,'DATA RECOJOS'!$A$4:$A$201,Config!$B$4) -> 1984.5
A13: Leads ganados entrantes: | B13: =COUNTIFS(Tiendas!$B$4:$B$176,$B$3,Tiendas!$M$4:$M$176,"Entrante",Tiendas!$J$4:$J$176,"Sí") -> 9 | E13: Margen vs moto (S/): | F13: =F11-F12 -> 1872.4492
A14: Leads ganados organicos | B14: =COUNTIFS(Tiendas!$B$4:$B$176,$B$3,Tiendas!$M$4:$M$176,"Orgánico",Tiendas!$J$4:$J$176,"Sí") -> 0 | E14: Comisión vendedor (S/): | F14: =B8 -> 232.8
A15: Leads totales gestionados: | B15: =B11+B12 -> 346 | E15: Costo total + comisión (S/): | F15: =F12+F14 -> 2217.3
A16: Leads ganados totales: | B16: =B13 -> 9 | E16: Margen - comisión (S/): | F16: =F11-F15 -> 1639.6492
A17: Cierre comercial (días, entrantes): | B17: =IFERROR(AVERAGEIFS(Tiendas!$H$4:$H$176,Tiendas!$B$4:$B$176,$B$3,Tiendas!$M$4:$M$176,"Entrante",Tiendas!$J$4:$J$176,"Sí"),"") -> 19.777778 | E17: Costo operativo por lead ganado (S/): | F17: =IF(B16=0,"",F12/B16) -> 220.5
A18: Cierre comercial (días, orgánicos): | B18: =IFERROR(AVERAGEIFS(Tiendas!$H$4:$H$176,Tiendas!$B$4:$B$176,$B$3,Tiendas!$M$4:$M$176,"Orgánico",Tiendas!$J$4:$J$176,"Sí"),"") | E18: Costo total por lead ganado + comisión (S/): | F18: =IF(B16=0,"",F15/B16) -> 246.36667
A19: Efectividad general: | B19: =IFERROR(B16/B15,"") -> 0.026011561 | E19: Ingreso por lead ganado (S/): | F19: =IF(B16=0,"",F11/B16) -> 428.54991
A20: Efectividad entrantes: | B20: =IFERROR(B13/B11,"") -> 0.047368421 | E20: Ticket promedio (S/ por envío entregado): | F20: =IF($B$6=0,"",F11/$B$6) -> 9.9405906
A21: Efectividad orgánica: | B21: =IFERROR(B14/B12,"") -> 0 | E21: Número de tiendas fulfillment: | F21: =COUNTIFS(Tiendas!$B$4:$B$176,$B$3,Tiendas!$I$4:$I$176,"Si") -> 2
A23: Top 3 tiendas con más envíos (Entregados)
A24: Ranking | B24: Tienda | C24: Envios entregados
A25: 1 | B25: {=IFERROR(INDEX(Helper_Vendedor!$A$4:$A$177,MATCH(1,Helper_Vendedor!$D$4:$D$177,0)),"-")} -> AVEFENIX3107 | C25: {=IFERROR(INDEX(Helper_Vendedor!$C$4:$C$177,MATCH(1,Helper_Vendedor!$D$4:$D$177,0)),"-")} -> 292
A26: 2 | B26: {=IFERROR(INDEX(Helper_Vendedor!$A$4:$A$177,MATCH(2,Helper_Vendedor!$D$4:$D$177,0)),"-")} -> Mishop Perú | C26: {=IFERROR(INDEX(Helper_Vendedor!$C$4:$C$177,MATCH(2,Helper_Vendedor!$D$4:$D$177,0)),"-")} -> 78
A27: 3 | B27: {=IFERROR(INDEX(Helper_Vendedor!$A$4:$A$177,MATCH(3,Helper_Vendedor!$D$4:$D$177,0)),"-")} -> OVERSOUL | C27: {=IFERROR(INDEX(Helper_Vendedor!$C$4:$C$177,MATCH(3,Helper_Vendedor!$D$4:$D$177,0)),"-")} -> 7

Sheet COMISIONES Y LEADS
A1: Vendedores — comisión por envíos (periodo único)
A3: Tabla de comisión por nivel
A4: Nivel | B4: Desde envíos | C4: Hasta envíos | D4: Comisión por envío (S/)
A5: Apus | B5: 0 | C5: 200 | D5: 0
A6: Pacha Mama | B6: 201 | C6: 400 | D6: 0.6
A7: Mama Quilla | B7: 401 | C7: 600 | D7: 0.7
A8: Inti | B8: 601 | C8: 800 | D8: 0.8
A9: Huiracocha | B9: 801 | C9: 1000 | D9: 1
A12: Comisión por vendedor (periodo)
A13: Vendedor | B13: Envíos del periodo | C13: Nivel | D13: Comisión por envío (S/) | E13: Comisión total (S/) | F13: Notas | G13: Leads entrantes (manual) | H13: Leads orgánicos (manual)
A14: ALEXIS | B14: =COUNTIFS('DATA ENVIOS'!$A$4:$A$2000,Config!$B$4,'DATA ENVIOS'!$K$4:$K$2000,$A14,'DATA ENVIOS'!$D$4:$D$2000,"Entregado") -> 164 | C14: =IF($B14="","",IF($B14<=200,"Apus",IF($B14<=400,"Pacha Mama",IF($B14<=600,"Mama Quilla",IF($B14<=800,"Inti","Huiracocha"))))) -> Apus | D14: =IF($C14="","",VLOOKUP($C14,$A$5:$D$9,4,FALSE)) -> 0 | E14: =IF($B14="","",$B14*$D14) -> 0 | G14: 276 | H14: 154
A15: SANDRA | B15: =COUNTIFS('DATA ENVIOS'!$A$4:$A$2000,Config!$B$4,'DATA ENVIOS'!$K$4:$K$2000,$A15,'DATA ENVIOS'!$D$4:$D$2000,"Entregado") -> 120 | C15: =IF($B15="","",IF($B15<=200,"Apus",IF($B15<=400,"Pacha Mama",IF($B15<=600,"Mama Quilla",IF($B15<=800,"Inti","Huiracocha"))))) -> Apus | D15: =IF($C15="","",VLOOKUP($C15,$A$5:$D$9,4,FALSE)) -> 0 | E15: =IF($B15="","",$B15*$D15) -> 0 | G15: 223 | H15: 3
A16: JORDAN | B16: =COUNTIFS('DATA ENVIOS'!$A$4:$A$2000,Config!$B$4,'DATA ENVIOS'!$K$4:$K$2000,$A16,'DATA ENVIOS'!$D$4:$D$2000,"Entregado") -> 388 | C16: =IF($B16="","",IF($B16<=200,"Apus",IF($B16<=400,"Pacha Mama",IF($B16<=600,"Mama Quilla",IF($B16<=800,"Inti","Huiracocha"))))) -> Pacha Mama | D16: =IF($C16="","",VLOOKUP($C16,$A$5:$D$9,4,FALSE)) -> 0.6 | E16: =IF($B16="","",$B16*$D16) -> 232.8 | G16: 190 | H16: 156
A17: CHRISTIAN | B17: =COUNTIFS('DATA ENVIOS'!$A$4:$A$2000,Config!$B$4,'DATA ENVIOS'!$K$4:$K$2000,$A17,'DATA ENVIOS'!$D$4:$D$2000,"Entregado") -> 179 | C17: =IF($B17="","",IF($B17<=200,"Apus",IF($B17<=400,"Pacha Mama",IF($B17<=600,"Mama Quilla",IF($B17<=800,"Inti","Huiracocha"))))) -> Apus | D17: =IF($C17="","",VLOOKUP($C17,$A$5:$D$9,4,FALSE)) -> 0 | E17: =IF($B17="","",$B17*$D17) -> 0 | G17: 282 | H17: 202
A18: SEBASTIAN | B18: =COUNTIFS('DATA ENVIOS'!$A$4:$A$2000,Config!$B$4,'DATA ENVIOS'!$K$4:$K$2000,$A18,'DATA ENVIOS'!$D$4:$D$2000,"Entregado") -> 125 | C18: =IF($B18="","",IF($B18<=200,"Apus",IF($B18<=400,"Pacha Mama",IF($B18<=600,"Mama Quilla",IF($B18<=800,"Inti","Huiracocha"))))) -> Apus | D18: =IF($C18="","",VLOOKUP($C18,$A$5:$D$9,4,FALSE)) -> 0 | E18: =IF($B18="","",$B18*$D18) -> 0 | G18: 256 | H18: 135

Sheet Ciclo_Vida
D1: CICLO DE VIDA
A3: Nombre tienda | B3: Vendedor | C3: Mes 1 (envíos) | D3: Mes 2 (envíos) | E3: Mes 3 (envíos) | F3: Mes 2 (recojos) | G3: Mes 3 (recojos) | H3: Mov. Mes 3 (total) | I3: Estado
A4: =IF(Tiendas!$A4="","",Tiendas!$A4) -> Forever20 | B4: =IF($A4="","",Tiendas!$B4) -> ALEXIS | C4: =IF($A4="","",COUNTIFS('DATA ENVIOS'!$B$4:$B$2000,$A4,'DATA ENVIOS'!$A$4:$A$2000,Config!$B$4,'DATA ENVIOS'!$D$4:$D$2000,"Entregado")) -> 12 | D4: =IF($A4="","",COUNTIFS('DATA ENVIOS'!$B$4:$B$2000,$A4,'DATA ENVIOS'!$A$4:$A$2000,Config!$B$9,'DATA ENVIOS'!$D$4:$D$2000,"Entregado")) -> 0 | E4: =IF($A4="","",COUNTIFS('DATA ENVIOS'!$B$4:$B$2000,$A4,'DATA ENVIOS'!$A$4:$A$2000,Config!$B$10,'DATA ENVIOS'!$D$4:$D$2000,"Entregado")) -> 0 | F4: =IF($A4="","",SUMIFS('DATA RECOJOS'!$D$4:$D$201,'DATA RECOJOS'!$B$4:$B$201,$A4,'DATA RECOJOS'!$A$4:$A$201,Config!$B$9)) -> 0 | G4: =IF($A4="","",SUMIFS('DATA RECOJOS'!$D$4:$D$201,'DATA RECOJOS'!$B$4:$B$201,$A4,'DATA RECOJOS'!$A$4:$A$201,Config!$B$10)) -> 0 | H4: =IF($A4="","",$E4+$G4) -> 0 | I4: =IF($A4="","",IF($H4>0,"Leads ganados activos",IF(($D4+$F4)>0,"Leads ganados a dar seguimiento",IF($C4>0,"Lead ganado perdido","-")))) -> Lead ganado perdido
A5: =IF(Tiendas!$A11="","",Tiendas!$A11) -> Joyful Shop | B5: =IF($A5="","",Tiendas!$B11) -> CHRISTIAN | C5: =IF($A5="","",COUNTIFS('DATA ENVIOS'!$B$4:$B$2000,$A5,'DATA ENVIOS'!$A$4:$A$2000,Config!$B$4,'DATA ENVIOS'!$D$4:$D$2000,"Entregado")) -> 21 | D5: =IF($A5="","",COUNTIFS('DATA ENVIOS'!$B$4:$B$2000,$A5,'DATA ENVIOS'!$A$4:$A$2000,Config!$B$9,'DATA ENVIOS'!$D$4:$D$2000,"Entregado")) -> 0 | E5: =IF($A5="","",COUNTIFS('DATA ENVIOS'!$B$4:$B$2000,$A5,'DATA ENVIOS'!$A$4:$A$2000,Config!$B$10,'DATA ENVIOS'!$D$4:$D$2000,"Entregado")) -> 0 | F5: =IF($A5="","",SUMIFS('DATA RECOJOS'!$D$4:$D$201,'DATA RECOJOS'!$B$4:$B$201,$A5,'DATA RECOJOS'!$A$4:$A$201,Config!$B$9)) -> 0 | G5: =IF($A5="","",SUMIFS('DATA RECOJOS'!$D$4:$D$201,'DATA RECOJOS'!$B$4:$B$201,$A5,'DATA RECOJOS'!$A$4:$A$201,Config!$B$10)) -> 0 | H5: =IF($A5="","",$E5+$G5) -> 0 | I5: =IF($A5="","",IF($H5>0,"Leads ganados activos",IF(($D5+$F5)>0,"Leads ganados a dar seguimiento",IF($C5>0,"Lead ganado perdido","-")))) -> Lead ganado perdido
A6: =IF(Tiendas!$A9="","",Tiendas!$A9) -> speechless_peru | B6: =IF($A6="","",Tiendas!$B9) -> CHRISTIAN | C6: =IF($A6="","",COUNTIFS('DATA ENVIOS'!$B$4:$B$2000,$A6,'DATA ENVIOS'!$A$4:$A$2000,Config!$B$4,'DATA ENVIOS'!$D$4:$D$2000,"Entregado")) -> 2 | D6: =IF($A6="","",COUNTIFS('DATA ENVIOS'!$B$4:$B$2000,$A6,'DATA ENVIOS'!$A$4:$A$2000,Config!$B$9,'DATA ENVIOS'!$D$4:$D$2000,"Entregado")) -> 0 | E6: =IF($A6="","",COUNTIFS('DATA ENVIOS'!$B$4:$B$2000,$A6,'DATA ENVIOS'!$A$4:$A$2000,Config!$B$10,'DATA ENVIOS'!$D$4:$D$2000,"Entregado")) -> 0 | F6: =IF($A6="","",SUMIFS('DATA RECOJOS'!$D$4:$D$201,'DATA RECOJOS'!$B$4:$B$201,$A6,'DATA RECOJOS'!$A$4:$A$201,Config!$B$9)) -> 0 | G6: =IF($A6="","",SUMIFS('DATA RECOJOS'!$D$4:$D$201,'DATA RECOJOS'!$B$4:$B$201,$A6,'DATA RECOJOS'!$A$4:$A$201,Config!$B$10)) -> 0 | H6: =IF($A6="","",$E6+$G6) -> 0 | I6: =IF($A6="","",IF($H6>0,"Leads ganados activos",IF(($D6+$F6)>0,"Leads ganados a dar seguimiento",IF($C6>0,"Lead ganado perdido","-")))) -> Lead ganado perdido
A7: =IF(Tiendas!$A38="","",Tiendas!$A38) -> ALTAVIRA | B7: =IF($A7="","",Tiendas!$B38) -> SANDRA | C7: =IF($A7="","",COUNTIFS('DATA ENVIOS'!$B$4:$B$2000,$A7,'DATA ENVIOS'!$A$4:$A$2000,Config!$B$4,'DATA ENVIOS'!$D$4:$D$2000,"Entregado")) -> 7 | D7: =IF($A7="","",COUNTIFS('DATA ENVIOS'!$B$4:$B$2000,$A7,'DATA ENVIOS'!$A$4:$A$2000,Config!$B$9,'DATA ENVIOS'!$D$4:$D$2000,"Entregado")) -> 0 | E7: =IF($A7="","",COUNTIFS('DATA ENVIOS'!$B$4:$B$2000,$A7,'DATA ENVIOS'!$A$4:$A$2000,Config!$B$10,'DATA ENVIOS'!$D$4:$D$2000,"Entregado")) -> 0 | F7: =IF($A7="","",SUMIFS('DATA RECOJOS'!$D$4:$D$201,'DATA RECOJOS'!$B$4:$B$201,$A7,'DATA RECOJOS'!$A$4:$A$201,Config!$B$9)) -> 0 | G7: =IF($A7="","",SUMIFS('DATA RECOJOS'!$D$4:$D$201,'DATA RECOJOS'!$B$4:$B$201,$A7,'DATA RECOJOS'!$A$4:$A$201,Config!$B$10)) -> 0 | H7: =IF($A7="","",$E7+$G7) -> 0 | I7: =IF($A7="","",IF($H7>0,"Leads ganados activos",IF(($D7+$F7)>0,"Leads ganados a dar seguimiento",IF($C7>0,"Lead ganado perdido","-")))) -> Lead ganado perdido
A8: =IF(Tiendas!$A6="","",Tiendas!$A6) -> FELIPE AMORIN CABALLERO | B8: =IF($A8="","",Tiendas!$B6) -> CHRISTIAN | C8: =IF($A8="","",COUNTIFS('DATA ENVIOS'!$B$4:$B$2000,$A8,'DATA ENVIOS'!$A$4:$A$2000,Config!$B$4,'DATA ENVIOS'!$D$4:$D$2000,"Entregado")) -> 1 | D8: =IF($A8="","",COUNTIFS('DATA ENVIOS'!$B$4:$B$2000,$A8,'DATA ENVIOS'!$A$4:$A$2000,Config!$B$9,'DATA ENVIOS'!$D$4:$D$2000,"Entregado")) -> 0 | E8: =IF($A8="","",COUNTIFS('DATA ENVIOS'!$B$4:$B$2000,$A8,'DATA ENVIOS'!$A$4:$A$2000,Config!$B$10,'DATA ENVIOS'!$D$4:$D$2000,"Entregado")) -> 0 | F8: =IF($A8="","",SUMIFS('DATA RECOJOS'!$D$4:$D$201,'DATA RECOJOS'!$B$4:$B$201,$A8,'DATA RECOJOS'!$A$4:$A$201,Config!$B$9)) -> 0 | G8: =IF($A8="","",SUMIFS('DATA RECOJOS'!$D$4:$D$201,'DATA RECOJOS'!$B$4:$B$201,$A8,'DATA RECOJOS'!$A$4:$A$201,Config!$B$10)) -> 0 | H8: =IF($A8="","",$E8+$G8) -> 0 | I8: =IF($A8="","",IF($H8>0,"Leads ganados activos",IF(($D8+$F8)>0,"Leads ganados a dar seguimiento",IF($C8>0,"Lead ganado perdido","-")))) -> Lead ganado perdido
A9: =IF(Tiendas!$A44="","",Tiendas!$A44) -> Joyería y Relojería Condor | B9: =IF($A9="","",Tiendas!$B44) -> CHRISTIAN | C9: =IF($A9="","",COUNTIFS('DATA ENVIOS'!$B$4:$B$2000,$A9,'DATA ENVIOS'!$A$4:$A$2000,Config!$B$4,'DATA ENVIOS'!$D$4:$D$2000,"Entregado")) -> 1 | D9: =IF($A9="","",COUNTIFS('DATA ENVIOS'!$B$4:$B$2000,$A9,'DATA ENVIOS'!$A$4:$A$2000,Config!$B$9,'DATA ENVIOS'!$D$4:$D$2000,"Entregado")) -> 0 | E9: =IF($A9="","",COUNTIFS('DATA ENVIOS'!$B$4:$B$2000,$A9,'DATA ENVIOS'!$A$4:$A$2000,Config!$B$10,'DATA ENVIOS'!$D$4:$D$2000,"Entregado")) -> 0 | F9: =IF($A9="","",SUMIFS('DATA RECOJOS'!$D$4:$D$201,'DATA RECOJOS'!$B$4:$B$201,$A9,'DATA RECOJOS'!$A$4:$A$201,Config!$B$9)) -> 0 | G9: =IF($A9="","",SUMIFS('DATA RECOJOS'!$D$4:$D$201,'DATA RECOJOS'!$B$4:$B$201,$A9,'DATA RECOJOS'!$A$4:$A$201,Config!$B$10)) -> 0 | H9: =IF($A9="","",$E9+$G9) -> 0 | I9: =IF($A9="","",IF($H9>0,"Leads ganados activos",IF(($D9+$F9)>0,"Leads ganados a dar seguimiento",IF($C9>0,"Lead ganado perdido","-")))) -> Lead ganado perdido
A10: =IF(Tiendas!$A45="","",Tiendas!$A45) -> Luixtech Store | B10: =IF($A10="","",Tiendas!$B45) -> ALEXIS | C10: =IF($A10="","",COUNTIFS('DATA ENVIOS'!$B$4:$B$2000,$A10,'DATA ENVIOS'!$A$4:$A$2000,Config!$B$4,'DATA ENVIOS'!$D$4:$D$2000,"Entregado")) -> 2 | D10: =IF($A10="","",COUNTIFS('DATA ENVIOS'!$B$4:$B$2000,$A10,'DATA ENVIOS'!$A$4:$A$2000,Config!$B$9,'DATA ENVIOS'!$D$4:$D$2000,"Entregado")) -> 0 | E10: =IF($A10="","",COUNTIFS('DATA ENVIOS'!$B$4:$B$2000,$A10,'DATA ENVIOS'!$A$4:$A$2000,Config!$B$10,'DATA ENVIOS'!$D$4:$D$2000,"Entregado")) -> 0 | F10: =IF($A10="","",SUMIFS('DATA RECOJOS'!$D$4:$D$201,'DATA RECOJOS'!$B$4:$B$201,$A10,'DATA RECOJOS'!$A$4:$A$201,Config!$B$9)) -> 0 | G10: =IF($A10="","",SUMIFS('DATA RECOJOS'!$D$4:$D$201,'DATA RECOJOS'!$B$4:$B$201,$A10,'DATA RECOJOS'!$A$4:$A$201,Config!$B$10)) -> 0 | H10: =IF($A10="","",$E10+$G10) -> 0 | I10: =IF($A10="","",IF($H10>0,"Leads ganados activos",IF(($D10+$F10)>0,"Leads ganados a dar seguimiento",IF($C10>0,"Lead ganado perdido","-")))) -> Lead ganado perdido
A11: =IF(Tiendas!$A60="","",Tiendas!$A60) -> Ozko | B11: =IF($A11="","",Tiendas!$B60) -> ALEXIS | C11: =IF($A11="","",COUNTIFS('DATA ENVIOS'!$B$4:$B$2000,$A11,'DATA ENVIOS'!$A$4:$A$2000,Config!$B$4,'DATA ENVIOS'!$D$4:$D$2000,"Entregado")) -> 3 | D11: =IF($A11="","",COUNTIFS('DATA ENVIOS'!$B$4:$B$2000,$A11,'DATA ENVIOS'!$A$4:$A$2000,Config!$B$9,'DATA ENVIOS'!$D$4:$D$2000,"Entregado")) -> 0 | E11: =IF($A11="","",COUNTIFS('DATA ENVIOS'!$B$4:$B$2000,$A11,'DATA ENVIOS'!$A$4:$A$2000,Config!$B$10,'DATA ENVIOS'!$D$4:$D$2000,"Entregado")) -> 0 | F11: =IF($A11="","",SUMIFS('DATA RECOJOS'!$D$4:$D$201,'DATA RECOJOS'!$B$4:$B$201,$A11,'DATA RECOJOS'!$A$4:$A$201,Config!$B$9)) -> 0 | G11: =IF($A11="","",SUMIFS('DATA RECOJOS'!$D$4:$D$201,'DATA RECOJOS'!$B$4:$B$201,$A11,'DATA RECOJOS'!$A$4:$A$201,Config!$B$10)) -> 0 | H11: =IF($A11="","",$E11+$G11) -> 0 | I11: =IF($A11="","",IF($H11>0,"Leads ganados activos",IF(($D11+$F11)>0,"Leads ganados a dar seguimiento",IF($C11>0,"Lead ganado perdido","-")))) -> Lead ganado perdido
A12: =IF(Tiendas!$A28="","",Tiendas!$A28) -> Joyeria Siberiana | B12: =IF($A12="","",Tiendas!$B28) -> SEBASTIAN | C12: =IF($A12="","",COUNTIFS('DATA ENVIOS'!$B$4:$B$2000,$A12,'DATA ENVIOS'!$A$4:$A$2000,Config!$B$4,'DATA ENVIOS'!$D$4:$D$2000,"Entregado")) -> 1 | D12: =IF($A12="","",COUNTIFS('DATA ENVIOS'!$B$4:$B$2000,$A12,'DATA ENVIOS'!$A$4:$A$2000,Config!$B$9,'DATA ENVIOS'!$D$4:$D$2000,"Entregado")) -> 0 | E12: =IF($A12="","",COUNTIFS('DATA ENVIOS'!$B$4:$B$2000,$A12,'DATA ENVIOS'!$A$4:$A$2000,Config!$B$10,'DATA ENVIOS'!$D$4:$D$2000,"Entregado")) -> 0 | F12: =IF($A12="","",SUMIFS('DATA RECOJOS'!$D$4:$D$201,'DATA RECOJOS'!$B$4:$B$201,$A12,'DATA RECOJOS'!$A$4:$A$201,Config!$B$9)) -> 0 | G12: =IF($A12="","",SUMIFS('DATA RECOJOS'!$D$4:$D$201,'DATA RECOJOS'!$B$4:$B$201,$A12,'DATA RECOJOS'!$A$4:$A$201,Config!$B$10)) -> 0 | H12: =IF($A12="","",$E12+$G12) -> 0 | I12: =IF($A12="","",IF($H12>0,"Leads ganados activos",IF(($D12+$F12)>0,"Leads ganados a dar seguimiento",IF($C12>0,"Lead ganado perdido","-")))) -> Lead ganado perdido
A13: =IF(Tiendas!$A16="","",Tiendas!$A16) -> Dmarc Gafas exclusivas | B13: =IF($A13="","",Tiendas!$B16) -> SANDRA | C13: =IF($A13="","",COUNTIFS('DATA ENVIOS'!$B$4:$B$2000,$A13,'DATA ENVIOS'!$A$4:$A$2000,Config!$B$4,'DATA ENVIOS'!$D$4:$D$2000,"Entregado")) -> 2 | D13: =IF($A13="","",COUNTIFS('DATA ENVIOS'!$B$4:$B$2000,$A13,'DATA ENVIOS'!$A$4:$A$2000,Config!$B$9,'DATA ENVIOS'!$D$4:$D$2000,"Entregado")) -> 0 | E13: =IF($A13="","",COUNTIFS('DATA ENVIOS'!$B$4:$B$2000,$A13,'DATA ENVIOS'!$A$4:$A$2000,Config!$B$10,'DATA ENVIOS'!$D$4:$D$2000,"Entregado")) -> 0 | F13: =IF($A13="","",SUMIFS('DATA RECOJOS'!$D$4:$D$201,'DATA RECOJOS'!$B$4:$B$201,$A13,'DATA RECOJOS'!$A$4:$A$201,Config!$B$9)) -> 0 | G13: =IF($A13="","",SUMIFS('DATA RECOJOS'!$D$4:$D$201,'DATA RECOJOS'!$B$4:$B$201,$A13,'DATA RECOJOS'!$A$4:$A$201,Config!$B$10)) -> 0 | H13: =IF($A13="","",$E13+$G13) -> 0 | I13: =IF($A13="","",IF($H13>0,"Leads ganados activos",IF(($D13+$F13)>0,"Leads ganados a dar seguimiento",IF($C13>0,"Lead ganado perdido","-")))) -> Lead ganado perdido
A14: =IF(Tiendas!$A10="","",Tiendas!$A10) -> Fame shop | B14: =IF($A14="","",Tiendas!$B10) -> CHRISTIAN | C14: =IF($A14="","",COUNTIFS('DATA ENVIOS'!$B$4:$B$2000,$A14,'DATA ENVIOS'!$A$4:$A$2000,Config!$B$4,'DATA ENVIOS'!$D$4:$D$2000,"Entregado")) -> 9 | D14: =IF($A14="","",COUNTIFS('DATA ENVIOS'!$B$4:$B$2000,$A14,'DATA ENVIOS'!$A$4:$A$2000,Config!$B$9,'DATA ENVIOS'!$D$4:$D$2000,"Entregado")) -> 0 | E14: =IF($A14="","",COUNTIFS('DATA ENVIOS'!$B$4:$B$2000,$A14,'DATA ENVIOS'!$A$4:$A$2000,Config!$B$10,'DATA ENVIOS'!$D$4:$D$2000,"Entregado")) -> 0 | F14: =IF($A14="","",SUMIFS('DATA RECOJOS'!$D$4:$D$201,'DATA RECOJOS'!$B$4:$B$201,$A14,'DATA RECOJOS'!$A$4:$A$201,Config!$B$9)) -> 0 | G14: =IF($A14="","",SUMIFS('DATA RECOJOS'!$D$4:$D$201,'DATA RECOJOS'!$B$4:$B$201,$A14,'DATA RECOJOS'!$A$4:$A$201,Config!$B$10)) -> 0 | H14: =IF($A14="","",$E14+$G14) -> 0 | I14: =IF($A14="","",IF($H14>0,"Leads ganados activos",IF(($D14+$F14)>0,"Leads ganados a dar seguimiento",IF($C14>0,"Lead ganado perdido","-")))) -> Lead ganado perdido
A15: =IF(Tiendas!$A14="","",Tiendas!$A14) -> Lune Atelier | B15: =IF($A15="","",Tiendas!$B14) -> JORDAN | C15: =IF($A15="","",COUNTIFS('DATA ENVIOS'!$B$4:$B$2000,$A15,'DATA ENVIOS'!$A$4:$A$2000,Config!$B$4,'DATA ENVIOS'!$D$4:$D$2000,"Entregado")) -> 4 | D15: =IF($A15="","",COUNTIFS('DATA ENVIOS'!$B$4:$B$2000,$A15,'DATA ENVIOS'!$A$4:$A$2000,Config!$B$9,'DATA ENVIOS'!$D$4:$D$2000,"Entregado")) -> 0 | E15: =IF($A15="","",COUNTIFS('DATA ENVIOS'!$B$4:$B$2000,$A15,'DATA ENVIOS'!$A$4:$A$2000,Config!$B$10,'DATA ENVIOS'!$D$4:$D$2000,"Entregado")) -> 0 | F15: =IF($A15="","",SUMIFS('DATA RECOJOS'!$D$4:$D$201,'DATA RECOJOS'!$B$4:$B$201,$A15,'DATA RECOJOS'!$A$4:$A$201,Config!$B$9)) -> 0 | G15: =IF($A15="","",SUMIFS('DATA RECOJOS'!$D$4:$D$201,'DATA RECOJOS'!$B$4:$B$201,$A15,'DATA RECOJOS'!$A$4:$A$201,Config!$B$10)) -> 0 | H15: =IF($A15="","",$E15+$G15) -> 0 | I15: =IF($A15="","",IF($H15>0,"Leads ganados activos",IF(($D15+$F15)>0,"Leads ganados a dar seguimiento",IF($C15>0,"Lead ganado perdido","-")))) -> Lead ganado perdido
A16: =IF(Tiendas!$A5="","",Tiendas!$A5) -> Seralta | B16: =IF($A16="","",Tiendas!$B5) -> ALEXIS | C16: =IF($A16="","",COUNTIFS('DATA ENVIOS'!$B$4:$B$2000,$A16,'DATA ENVIOS'!$A$4:$A$2000,Config!$B$4,'DATA ENVIOS'!$D$4:$D$2000,"Entregado")) -> 66 | D16: =IF($A16="","",COUNTIFS('DATA ENVIOS'!$B$4:$B$2000,$A16,'DATA ENVIOS'!$A$4:$A$2000,Config!$B$9,'DATA ENVIOS'!$D$4:$D$2000,"Entregado")) -> 0 | E16: =IF($A16="","",COUNTIFS('DATA ENVIOS'!$B$4:$B$2000,$A16,'DATA ENVIOS'!$A$4:$A$2000,Config!$B$10,'DATA ENVIOS'!$D$4:$D$2000,"Entregado")) -> 0 | F16: =IF($A16="","",SUMIFS('DATA RECOJOS'!$D$4:$D$201,'DATA RECOJOS'!$B$4:$B$201,$A16,'DATA RECOJOS'!$A$4:$A$201,Config!$B$9)) -> 0 | G16: =IF($A16="","",SUMIFS('DATA RECOJOS'!$D$4:$D$201,'DATA RECOJOS'!$B$4:$B$201,$A16,'DATA RECOJOS'!$A$4:$A$201,Config!$B$10)) -> 0 | H16: =IF($A16="","",$E16+$G16) -> 0 | I16: =IF($A16="","",IF($H16>0,"Leads ganados activos",IF(($D16+$F16)>0,"Leads ganados a dar seguimiento",IF($C16>0,"Lead ganado perdido","-")))) -> Lead ganado perdido
A17: =IF(Tiendas!$A33="","",Tiendas!$A33) -> Izinova store Perú | B17: =IF($A17="","",Tiendas!$B33) -> SANDRA | C17: =IF($A17="","",COUNTIFS('DATA ENVIOS'!$B$4:$B$2000,$A17,'DATA ENVIOS'!$A$4:$A$2000,Config!$B$4,'DATA ENVIOS'!$D$4:$D$2000,"Entregado")) -> 12 | D17: =IF($A17="","",COUNTIFS('DATA ENVIOS'!$B$4:$B$2000,$A17,'DATA ENVIOS'!$A$4:$A$2000,Config!$B$9,'DATA ENVIOS'!$D$4:$D$2000,"Entregado")) -> 0 | E17: =IF($A17="","",COUNTIFS('DATA ENVIOS'!$B$4:$B$2000,$A17,'DATA ENVIOS'!$A$4:$A$2000,Config!$B$10,'DATA ENVIOS'!$D$4:$D$2000,"Entregado")) -> 0 | F17: =IF($A17="","",SUMIFS('DATA RECOJOS'!$D$4:$D$201,'DATA RECOJOS'!$B$4:$B$201,$A17,'DATA RECOJOS'!$A$4:$A$201,Config!$B$9)) -> 0 | G17: =IF($A17="","",SUMIFS('DATA RECOJOS'!$D$4:$D$201,'DATA RECOJOS'!$B$4:$B$201,$A17,'DATA RECOJOS'!$A$4:$A$201,Config!$B$10)) -> 0 | H17: =IF($A17="","",$E17+$G17) -> 0 | I17: =IF($A17="","",IF($H17>0,"Leads ganados activos",IF(($D17+$F17)>0,"Leads ganados a dar seguimiento",IF($C17>0,"Lead ganado perdido","-")))) -> Lead ganado perdido
A18: =IF(Tiendas!$A7="","",Tiendas!$A7) -> Vrillita | B18: =IF($A18="","",Tiendas!$B7) -> CHRISTIAN | C18: =IF($A18="","",COUNTIFS('DATA ENVIOS'!$B$4:$B$2000,$A18,'DATA ENVIOS'!$A$4:$A$2000,Config!$B$4,'DATA ENVIOS'!$D$4:$D$2000,"Entregado")) -> 1 | D18: =IF($A18="","",COUNTIFS('DATA ENVIOS'!$B$4:$B$2000,$A18,'DATA ENVIOS'!$A$4:$A$2000,Config!$B$9,'DATA ENVIOS'!$D$4:$D$2000,"Entregado")) -> 0 | E18: =IF($A18="","",COUNTIFS('DATA ENVIOS'!$B$4:$B$2000,$A18,'DATA ENVIOS'!$A$4:$A$2000,Config!$B$10,'DATA ENVIOS'!$D$4:$D$2000,"Entregado")) -> 0 | F18: =IF($A18="","",SUMIFS('DATA RECOJOS'!$D$4:$D$201,'DATA RECOJOS'!$B$4:$B$201,$A18,'DATA RECOJOS'!$A$4:$A$201,Config!$B$9)) -> 0 | G18: =IF($A18="","",SUMIFS('DATA RECOJOS'!$D$4:$D$201,'DATA RECOJOS'!$B$4:$B$201,$A18,'DATA RECOJOS'!$A$4:$A$201,Config!$B$10)) -> 0 | H18: =IF($A18="","",$E18+$G18) -> 0 | I18: =IF($A18="","",IF($H18>0,"Leads ganados activos",IF(($D18+$F18)>0,"Leads ganados a dar seguimiento",IF($C18>0,"Lead ganado perdido","-")))) -> Lead ganado perdido
A19: =IF(Tiendas!$A57="","",Tiendas!$A57) -> Ponte Bacán | B19: =IF($A19="","",Tiendas!$B57) -> ALEXIS | C19: =IF($A19="","",COUNTIFS('DATA ENVIOS'!$B$4:$B$2000,$A19,'DATA ENVIOS'!$A$4:$A$2000,Config!$B$4,'DATA ENVIOS'!$D$4:$D$2000,"Entregado")) -> 10 | D19: =IF($A19="","",COUNTIFS('DATA ENVIOS'!$B$4:$B$2000,$A19,'DATA ENVIOS'!$A$4:$A$2000,Config!$B$9,'DATA ENVIOS'!$D$4:$D$2000,"Entregado")) -> 0 | E19: =IF($A19="","",COUNTIFS('DATA ENVIOS'!$B$4:$B$2000,$A19,'DATA ENVIOS'!$A$4:$A$2000,Config!$B$10,'DATA ENVIOS'!$D$4:$D$2000,"Entregado")) -> 0 | F19: =IF($A19="","",SUMIFS('DATA RECOJOS'!$D$4:$D$201,'DATA RECOJOS'!$B$4:$B$201,$A19,'DATA RECOJOS'!$A$4:$A$201,Config!$B$9)) -> 0 | G19: =IF($A19="","",SUMIFS('DATA RECOJOS'!$D$4:$D$201,'DATA RECOJOS'!$B$4:$B$201,$A19,'DATA RECOJOS'!$A$4:$A$201,Config!$B$10)) -> 0 | H19: =IF($A19="","",$E19+$G19) -> 0 | I19: =IF($A19="","",IF($H19>0,"Leads ganados activos",IF(($D19+$F19)>0,"Leads ganados a dar seguimiento",IF($C19>0,"Lead ganado perdido","-")))) -> Lead ganado perdido
A20: =IF(Tiendas!$A49="","",Tiendas!$A49) -> Greeh gar | B20: =IF($A20="","",Tiendas!$B49) -> CHRISTIAN | C20: =IF($A20="","",COUNTIFS('DATA ENVIOS'!$B$4:$B$2000,$A20,'DATA ENVIOS'!$A$4:$A$2000,Config!$B$4,'DATA ENVIOS'!$D$4:$D$2000,"Entregado")) -> 1 | D20: =IF($A20="","",COUNTIFS('DATA ENVIOS'!$B$4:$B$2000,$A20,'DATA ENVIOS'!$A$4:$A$2000,Config!$B$9,'DATA ENVIOS'!$D$4:$D$2000,"Entregado")) -> 0 | E20: =IF($A20="","",COUNTIFS('DATA ENVIOS'!$B$4:$B$2000,$A20,'DATA ENVIOS'!$A$4:$A$2000,Config!$B$10,'DATA ENVIOS'!$D$4:$D$2000,"Entregado")) -> 0 | F20: =IF($A20="","",SUMIFS('DATA RECOJOS'!$D$4:$D$201,'DATA RECOJOS'!$B$4:$B$201,$A20,'DATA RECOJOS'!$A$4:$A$201,Config!$B$9)) -> 0 | G20: =IF($A20="","",SUMIFS('DATA RECOJOS'!$D$4:$D$201,'DATA RECOJOS'!$B$4:$B$201,$A20,'DATA RECOJOS'!$A$4:$A$201,Config!$B$10)) -> 0 | H20: =IF($A20="","",$E20+$G20) -> 0 | I20: =IF($A20="","",IF($H20>0,"Leads ganados activos",IF(($D20+$F20)>0,"Leads ganados a dar seguimiento",IF($C20>0,"Lead ganado perdido","-")))) -> Lead ganado perdido
A21: =IF(Tiendas!$A54="","",Tiendas!$A54) -> GAMONA | B21: =IF($A21="","",Tiendas!$B54) -> CHRISTIAN | C21: =IF($A21="","",COUNTIFS('DATA ENVIOS'!$B$4:$B$2000,$A21,'DATA ENVIOS'!$A$4:$A$2000,Config!$B$4,'DATA ENVIOS'!$D$4:$D$2000,"Entregado")) -> 1 | D21: =IF($A21="","",COUNTIFS('DATA ENVIOS'!$B$4:$B$2000,$A21,'DATA ENVIOS'!$A$4:$A$2000,Config!$B$9,'DATA ENVIOS'!$D$4:$D$2000,"Entregado")) -> 0 | E21: =IF($A21="","",COUNTIFS('DATA ENVIOS'!$B$4:$B$2000,$A21,'DATA ENVIOS'!$A$4:$A$2000,Config!$B$10,'DATA ENVIOS'!$D$4:$D$2000,"Entregado")) -> 0 | F21: =IF($A21="","",SUMIFS('DATA RECOJOS'!$D$4:$D$201,'DATA RECOJOS'!$B$4:$B$201,$A21,'DATA RECOJOS'!$A$4:$A$201,Config!$B$9)) -> 0 | G21: =IF($A21="","",SUMIFS('DATA RECOJOS'!$D$4:$D$201,'DATA RECOJOS'!$B$4:$B$201,$A21,'DATA RECOJOS'!$A$4:$A$201,Config!$B$10)) -> 0 | H21: =IF($A21="","",$E21+$G21) -> 0 | I21: =IF($A21="","",IF($H21>0,"Leads ganados activos",IF(($D21+$F21)>0,"Leads ganados a dar seguimiento",IF($C21>0,"Lead ganado perdido","-")))) -> Lead ganado perdido
A22: =IF(Tiendas!$A61="","",Tiendas!$A61) -> Emerald | B22: =IF($A22="","",Tiendas!$B61) -> ALEXIS | C22: =IF($A22="","",COUNTIFS('DATA ENVIOS'!$B$4:$B$2000,$A22,'DATA ENVIOS'!$A$4:$A$2000,Config!$B$4,'DATA ENVIOS'!$D$4:$D$2000,"Entregado")) -> 2 | D22: =IF($A22="","",COUNTIFS('DATA ENVIOS'!$B$4:$B$2000,$A22,'DATA ENVIOS'!$A$4:$A$2000,Config!$B$9,'DATA ENVIOS'!$D$4:$D$2000,"Entregado")) -> 0 | E22: =IF($A22="","",COUNTIFS('DATA ENVIOS'!$B$4:$B$2000,$A22,'DATA ENVIOS'!$A$4:$A$2000,Config!$B$10,'DATA ENVIOS'!$D$4:$D$2000,"Entregado")) -> 0 | F22: =IF($A22="","",SUMIFS('DATA RECOJOS'!$D$4:$D$201,'DATA RECOJOS'!$B$4:$B$201,$A22,'DATA RECOJOS'!$A$4:$A$201,Config!$B$9)) -> 0 | G22: =IF($A22="","",SUMIFS('DATA RECOJOS'!$D$4:$D$201,'DATA RECOJOS'!$B$4:$B$201,$A22,'DATA RECOJOS'!$A$4:$A$201,Config!$B$10)) -> 0 | H22: =IF($A22="","",$E22+$G22) -> 0 | I22: =IF($A22="","",IF($H22>0,"Leads ganados activos",IF(($D22+$F22)>0,"Leads ganados a dar seguimiento",IF($C22>0,"Lead ganado perdido","-")))) -> Lead ganado perdido
A23: =IF(Tiendas!$A8="","",Tiendas!$A8) -> Tiens By Lucy | B23: =IF($A23="","",Tiendas!$B8) -> CHRISTIAN | C23: =IF($A23="","",COUNTIFS('DATA ENVIOS'!$B$4:$B$2000,$A23,'DATA ENVIOS'!$A$4:$A$2000,Config!$B$4,'DATA ENVIOS'!$D$4:$D$2000,"Entregado")) -> 1 | D23: =IF($A23="","",COUNTIFS('DATA ENVIOS'!$B$4:$B$2000,$A23,'DATA ENVIOS'!$A$4:$A$2000,Config!$B$9,'DATA ENVIOS'!$D$4:$D$2000,"Entregado")) -> 0 | E23: =IF($A23="","",COUNTIFS('DATA ENVIOS'!$B$4:$B$2000,$A23,'DATA ENVIOS'!$A$4:$A$2000,Config!$B$10,'DATA ENVIOS'!$D$4:$D$2000,"Entregado")) -> 0 | F23: =IF($A23="","",SUMIFS('DATA RECOJOS'!$D$4:$D$201,'DATA RECOJOS'!$B$4:$B$201,$A23,'DATA RECOJOS'!$A$4:$A$201,Config!$B$9)) -> 0 | G23: =IF($A23="","",SUMIFS('DATA RECOJOS'!$D$4:$D$201,'DATA RECOJOS'!$B$4:$B$201,$A23,'DATA RECOJOS'!$A$4:$A$201,Config!$B$10)) -> 0 | H23: =IF($A23="","",$E23+$G23) -> 0 | I23: =IF($A23="","",IF($H23>0,"Leads ganados activos",IF(($D23+$F23)>0,"Leads ganados a dar seguimiento",IF($C23>0,"Lead ganado perdido","-")))) -> Lead ganado perdido
A24: =IF(Tiendas!$A31="","",Tiendas!$A31) -> Verveo | B24: =IF($A24="","",Tiendas!$B31) -> JORDAN | C24: =IF($A24="","",COUNTIFS('DATA ENVIOS'!$B$4:$B$2000,$A24,'DATA ENVIOS'!$A$4:$A$2000,Config!$B$4,'DATA ENVIOS'!$D$4:$D$2000,"Entregado")) -> 1 | D24: =IF($A24="","",COUNTIFS('DATA ENVIOS'!$B$4:$B$2000,$A24,'DATA ENVIOS'!$A$4:$A$2000,Config!$B$9,'DATA ENVIOS'!$D$4:$D$2000,"Entregado")) -> 0 | E24: =IF($A24="","",COUNTIFS('DATA ENVIOS'!$B$4:$B$2000,$A24,'DATA ENVIOS'!$A$4:$A$2000,Config!$B$10,'DATA ENVIOS'!$D$4:$D$2000,"Entregado")) -> 0 | F24: =IF($A24="","",SUMIFS('DATA RECOJOS'!$D$4:$D$201,'DATA RECOJOS'!$B$4:$B$201,$A24,'DATA RECOJOS'!$A$4:$A$201,Config!$B$9)) -> 0 | G24: =IF($A24="","",SUMIFS('DATA RECOJOS'!$D$4:$D$201,'DATA RECOJOS'!$B$4:$B$201,$A24,'DATA RECOJOS'!$A$4:$A$201,Config!$B$10)) -> 0 | H24: =IF($A24="","",$E24+$G24) -> 0 | I24: =IF($A24="","",IF($H24>0,"Leads ganados activos",IF(($D24+$F24)>0,"Leads ganados a dar seguimiento",IF($C24>0,"Lead ganado perdido","-")))) -> Lead ganado perdido
A25: =IF(Tiendas!$A46="","",Tiendas!$A46) -> MonoCar | B25: =IF($A25="","",Tiendas!$B46) -> CHRISTIAN | C25: =IF($A25="","",COUNTIFS('DATA ENVIOS'!$B$4:$B$2000,$A25,'DATA ENVIOS'!$A$4:$A$2000,Config!$B$4,'DATA ENVIOS'!$D$4:$D$2000,"Entregado")) -> 81 | D25: =IF($A25="","",COUNTIFS('DATA ENVIOS'!$B$4:$B$2000,$A25,'DATA ENVIOS'!$A$4:$A$2000,Config!$B$9,'DATA ENVIOS'!$D$4:$D$2000,"Entregado")) -> 0 | E25: =IF($A25="","",COUNTIFS('DATA ENVIOS'!$B$4:$B$2000,$A25,'DATA ENVIOS'!$A$4:$A$2000,Config!$B$10,'DATA ENVIOS'!$D$4:$D$2000,"Entregado")) -> 0 | F25: =IF($A25="","",SUMIFS('DATA RECOJOS'!$D$4:$D$201,'DATA RECOJOS'!$B$4:$B$201,$A25,'DATA RECOJOS'!$A$4:$A$201,Config!$B$9)) -> 0 | G25: =IF($A25="","",SUMIFS('DATA RECOJOS'!$D$4:$D$201,'DATA RECOJOS'!$B$4:$B$201,$A25,'DATA RECOJOS'!$A$4:$A$201,Config!$B$10)) -> 0 | H25: =IF($A25="","",$E25+$G25) -> 0 | I25: =IF($A25="","",IF($H25>0,"Leads ganados activos",IF(($D25+$F25)>0,"Leads ganados a dar seguimiento",IF($C25>0,"Lead ganado perdido","-")))) -> Lead ganado perdido
A26: =IF(Tiendas!$A12="","",Tiendas!$A12) -> Industrias Osorio | B26: =IF($A26="","",Tiendas!$B12) -> JORDAN | C26: =IF($A26="","",COUNTIFS('DATA ENVIOS'!$B$4:$B$2000,$A26,'DATA ENVIOS'!$A$4:$A$2000,Config!$B$4,'DATA ENVIOS'!$D$4:$D$2000,"Entregado")) -> 1 | D26: =IF($A26="","",COUNTIFS('DATA ENVIOS'!$B$4:$B$2000,$A26,'DATA ENVIOS'!$A$4:$A$2000,Config!$B$9,'DATA ENVIOS'!$D$4:$D$2000,"Entregado")) -> 0 | E26: =IF($A26="","",COUNTIFS('DATA ENVIOS'!$B$4:$B$2000,$A26,'DATA ENVIOS'!$A$4:$A$2000,Config!$B$10,'DATA ENVIOS'!$D$4:$D$2000,"Entregado")) -> 0 | F26: =IF($A26="","",SUMIFS('DATA RECOJOS'!$D$4:$D$201,'DATA RECOJOS'!$B$4:$B$201,$A26,'DATA RECOJOS'!$A$4:$A$201,Config!$B$9)) -> 0 | G26: =IF($A26="","",SUMIFS('DATA RECOJOS'!$D$4:$D$201,'DATA RECOJOS'!$B$4:$B$201,$A26,'DATA RECOJOS'!$A$4:$A$201,Config!$B$10)) -> 0 | H26: =IF($A26="","",$E26+$G26) -> 0 | I26: =IF($A26="","",IF($H26>0,"Leads ganados activos",IF(($D26+$F26)>0,"Leads ganados a dar seguimiento",IF($C26>0,"Lead ganado perdido","-")))) -> Lead ganado perdido
A27: =IF(Tiendas!$A39="","",Tiendas!$A39) -> MC ORIGINALS | B27: =IF($A27="","",Tiendas!$B39) -> SEBASTIAN | C27: =IF($A27="","",COUNTIFS('DATA ENVIOS'!$B$4:$B$2000,$A27,'DATA ENVIOS'!$A$4:$A$2000,Config!$B$4,'DATA ENVIOS'!$D$4:$D$2000,"Entregado")) -> 1 | D27: =IF($A27="","",COUNTIFS('DATA ENVIOS'!$B$4:$B$2000,$A27,'DATA ENVIOS'!$A$4:$A$2000,Config!$B$9,'DATA ENVIOS'!$D$4:$D$2000,"Entregado")) -> 0 | E27: =IF($A27="","",COUNTIFS('DATA ENVIOS'!$B$4:$B$2000,$A27,'DATA ENVIOS'!$A$4:$A$2000,Config!$B$10,'DATA ENVIOS'!$D$4:$D$2000,"Entregado")) -> 0 | F27: =IF($A27="","",SUMIFS('DATA RECOJOS'!$D$4:$D$201,'DATA RECOJOS'!$B$4:$B$201,$A27,'DATA RECOJOS'!$A$4:$A$201,Config!$B$9)) -> 0 | G27: =IF($A27="","",SUMIFS('DATA RECOJOS'!$D$4:$D$201,'DATA RECOJOS'!$B$4:$B$201,$A27,'DATA RECOJOS'!$A$4:$A$201,Config!$B$10)) -> 0 | H27: =IF($A27="","",$E27+$G27) -> 0 | I27: =IF($A27="","",IF($H27>0,"Leads ganados activos",IF(($D27+$F27)>0,"Leads ganados a dar seguimiento",IF($C27>0,"Lead ganado perdido","-")))) -> Lead ganado perdido
A28: =IF(Tiendas!$A47="","",Tiendas!$A47) -> Hesla Import | B28: =IF($A28="","",Tiendas!$B47) -> ALEXIS | C28: =IF($A28="","",COUNTIFS('DATA ENVIOS'!$B$4:$B$2000,$A28,'DATA ENVIOS'!$A$4:$A$2000,Config!$B$4,'DATA ENVIOS'!$D$4:$D$2000,"Entregado")) -> 16 | D28: =IF($A28="","",COUNTIFS('DATA ENVIOS'!$B$4:$B$2000,$A28,'DATA ENVIOS'!$A$4:$A$2000,Config!$B$9,'DATA ENVIOS'!$D$4:$D$2000,"Entregado")) -> 0 | E28: =IF($A28="","",COUNTIFS('DATA ENVIOS'!$B$4:$B$2000,$A28,'DATA ENVIOS'!$A$4:$A$2000,Config!$B$10,'DATA ENVIOS'!$D$4:$D$2000,"Entregado")) -> 0 | F28: =IF($A28="","",SUMIFS('DATA RECOJOS'!$D$4:$D$201,'DATA RECOJOS'!$B$4:$B$201,$A28,'DATA RECOJOS'!$A$4:$A$201,Config!$B$9)) -> 0 | G28: =IF($A28="","",SUMIFS('DATA RECOJOS'!$D$4:$D$201,'DATA RECOJOS'!$B$4:$B$201,$A28,'DATA RECOJOS'!$A$4:$A$201,Config!$B$10)) -> 0 | H28: =IF($A28="","",$E28+$G28) -> 0 | I28: =IF($A28="","",IF($H28>0,"Leads ganados activos",IF(($D28+$F28)>0,"Leads ganados a dar seguimiento",IF($C28>0,"Lead ganado perdido","-")))) -> Lead ganado perdido
A29: =IF(Tiendas!$A18="","",Tiendas!$A18) -> Elsa Elizabeth Angeles Carrasco | B29: =IF($A29="","",Tiendas!$B18) -> SEBASTIAN | C29: =IF($A29="","",COUNTIFS('DATA ENVIOS'!$B$4:$B$2000,$A29,'DATA ENVIOS'!$A$4:$A$2000,Config!$B$4,'DATA ENVIOS'!$D$4:$D$2000,"Entregado")) -> 1 | D29: =IF($A29="","",COUNTIFS('DATA ENVIOS'!$B$4:$B$2000,$A29,'DATA ENVIOS'!$A$4:$A$2000,Config!$B$9,'DATA ENVIOS'!$D$4:$D$2000,"Entregado")) -> 0 | E29: =IF($A29="","",COUNTIFS('DATA ENVIOS'!$B$4:$B$2000,$A29,'DATA ENVIOS'!$A$4:$A$2000,Config!$B$10,'DATA ENVIOS'!$D$4:$D$2000,"Entregado")) -> 0 | F29: =IF($A29="","",SUMIFS('DATA RECOJOS'!$D$4:$D$201,'DATA RECOJOS'!$B$4:$B$201,$A29,'DATA RECOJOS'!$A$4:$A$201,Config!$B$9)) -> 0 | G29: =IF($A29="","",SUMIFS('DATA RECOJOS'!$D$4:$D$201,'DATA RECOJOS'!$B$4:$B$201,$A29,'DATA RECOJOS'!$A$4:$A$201,Config!$B$10)) -> 0 | H29: =IF($A29="","",$E29+$G29) -> 0 | I29: =IF($A29="","",IF($H29>0,"Leads ganados activos",IF(($D29+$F29)>0,"Leads ganados a dar seguimiento",IF($C29>0,"Lead ganado perdido","-")))) -> Lead ganado perdido
A30: =IF(Tiendas!$A22="","",Tiendas!$A22) -> Aesthetics Perú | B30: =IF($A30="","",Tiendas!$B22) -> SEBASTIAN | C30: =IF($A30="","",COUNTIFS('DATA ENVIOS'!$B$4:$B$2000,$A30,'DATA ENVIOS'!$A$4:$A$2000,Config!$B$4,'DATA ENVIOS'!$D$4:$D$2000,"Entregado")) -> 23 | D30: =IF($A30="","",COUNTIFS('DATA ENVIOS'!$B$4:$B$2000,$A30,'DATA ENVIOS'!$A$4:$A$2000,Config!$B$9,'DATA ENVIOS'!$D$4:$D$2000,"Entregado")) -> 0 | E30: =IF($A30="","",COUNTIFS('DATA ENVIOS'!$B$4:$B$2000,$A30,'DATA ENVIOS'!$A$4:$A$2000,Config!$B$10,'DATA ENVIOS'!$D$4:$D$2000,"Entregado")) -> 0 | F30: =IF($A30="","",SUMIFS('DATA RECOJOS'!$D$4:$D$201,'DATA RECOJOS'!$B$4:$B$201,$A30,'DATA RECOJOS'!$A$4:$A$201,Config!$B$9)) -> 0 | G30: =IF($A30="","",SUMIFS('DATA RECOJOS'!$D$4:$D$201,'DATA RECOJOS'!$B$4:$B$201,$A30,'DATA RECOJOS'!$A$4:$A$201,Config!$B$10)) -> 0 | H30: =IF($A30="","",$E30+$G30) -> 0 | I30: =IF($A30="","",IF($H30>0,"Leads ganados activos",IF(($D30+$F30)>0,"Leads ganados a dar seguimiento",IF($C30>0,"Lead ganado perdido","-")))) -> Lead ganado perdido
A31: =IF(Tiendas!$A26="","",Tiendas!$A26) -> Jean Paul Salazar Maticorena | B31: =IF($A31="","",Tiendas!$B26) -> ALEXIS | C31: =IF($A31="","",COUNTIFS('DATA ENVIOS'!$B$4:$B$2000,$A31,'DATA ENVIOS'!$A$4:$A$2000,Config!$B$4,'DATA ENVIOS'!$D$4:$D$2000,"Entregado")) -> 5 | D31: =IF($A31="","",COUNTIFS('DATA ENVIOS'!$B$4:$B$2000,$A31,'DATA ENVIOS'!$A$4:$A$2000,Config!$B$9,'DATA ENVIOS'!$D$4:$D$2000,"Entregado")) -> 0 | E31: =IF($A31="","",COUNTIFS('DATA ENVIOS'!$B$4:$B$2000,$A31,'DATA ENVIOS'!$A$4:$A$2000,Config!$B$10,'DATA ENVIOS'!$D$4:$D$2000,"Entregado")) -> 0 | F31: =IF($A31="","",SUMIFS('DATA RECOJOS'!$D$4:$D$201,'DATA RECOJOS'!$B$4:$B$201,$A31,'DATA RECOJOS'!$A$4:$A$201,Config!$B$9)) -> 0 | G31: =IF($A31="","",SUMIFS('DATA RECOJOS'!$D$4:$D$201,'DATA RECOJOS'!$B$4:$B$201,$A31,'DATA RECOJOS'!$A$4:$A$201,Config!$B$10)) -> 0 | H31: =IF($A31="","",$E31+$G31) -> 0 | I31: =IF($A31="","",IF($H31>0,"Leads ganados activos",IF(($D31+$F31)>0,"Leads ganados a dar seguimiento",IF($C31>0,"Lead ganado perdido","-")))) -> Lead ganado perdido
A32: =IF(Tiendas!$A58="","",Tiendas!$A58) -> Lumea Makeup | B32: =IF($A32="","",Tiendas!$B58) -> SEBASTIAN | C32: =IF($A32="","",COUNTIFS('DATA ENVIOS'!$B$4:$B$2000,$A32,'DATA ENVIOS'!$A$4:$A$2000,Config!$B$4,'DATA ENVIOS'!$D$4:$D$2000,"Entregado")) -> 8 | D32: =IF($A32="","",COUNTIFS('DATA ENVIOS'!$B$4:$B$2000,$A32,'DATA ENVIOS'!$A$4:$A$2000,Config!$B$9,'DATA ENVIOS'!$D$4:$D$2000,"Entregado")) -> 0 | E32: =IF($A32="","",COUNTIFS('DATA ENVIOS'!$B$4:$B$2000,$A32,'DATA ENVIOS'!$A$4:$A$2000,Config!$B$10,'DATA ENVIOS'!$D$4:$D$2000,"Entregado")) -> 0 | F32: =IF($A32="","",SUMIFS('DATA RECOJOS'!$D$4:$D$201,'DATA RECOJOS'!$B$4:$B$201,$A32,'DATA RECOJOS'!$A$4:$A$201,Config!$B$9)) -> 0 | G32: =IF($A32="","",SUMIFS('DATA RECOJOS'!$D$4:$D$201,'DATA RECOJOS'!$B$4:$B$201,$A32,'DATA RECOJOS'!$A$4:$A$201,Config!$B$10)) -> 0 | H32: =IF($A32="","",$E32+$G32) -> 0 | I32: =IF($A32="","",IF($H32>0,"Leads ganados activos",IF(($D32+$F32)>0,"Leads ganados a dar seguimiento",IF($C32>0,"Lead ganado perdido","-")))) -> Lead ganado perdido
A33: =IF(Tiendas!$A62="","",Tiendas!$A62) -> Lalazuliv | B33: =IF($A33="","",Tiendas!$B62) -> CHRISTIAN | C33: =IF($A33="","",COUNTIFS('DATA ENVIOS'!$B$4:$B$2000,$A33,'DATA ENVIOS'!$A$4:$A$2000,Config!$B$4,'DATA ENVIOS'!$D$4:$D$2000,"Entregado")) -> 2 | D33: =IF($A33="","",COUNTIFS('DATA ENVIOS'!$B$4:$B$2000,$A33,'DATA ENVIOS'!$A$4:$A$2000,Config!$B$9,'DATA ENVIOS'!$D$4:$D$2000,"Entregado")) -> 0 | E33: =IF($A33="","",COUNTIFS('DATA ENVIOS'!$B$4:$B$2000,$A33,'DATA ENVIOS'!$A$4:$A$2000,Config!$B$10,'DATA ENVIOS'!$D$4:$D$2000,"Entregado")) -> 0 | F33: =IF($A33="","",SUMIFS('DATA RECOJOS'!$D$4:$D$201,'DATA RECOJOS'!$B$4:$B$201,$A33,'DATA RECOJOS'!$A$4:$A$201,Config!$B$9)) -> 0 | G33: =IF($A33="","",SUMIFS('DATA RECOJOS'!$D$4:$D$201,'DATA RECOJOS'!$B$4:$B$201,$A33,'DATA RECOJOS'!$A$4:$A$201,Config!$B$10)) -> 0 | H33: =IF($A33="","",$E33+$G33) -> 0 | I33: =IF($A33="","",IF($H33>0,"Leads ganados activos",IF(($D33+$F33)>0,"Leads ganados a dar seguimiento",IF($C33>0,"Lead ganado perdido","-")))) -> Lead ganado perdido
A34: =IF(Tiendas!$A56="","",Tiendas!$A56) -> RyJ Store | B34: =IF($A34="","",Tiendas!$B56) -> SEBASTIAN | C34: =IF($A34="","",COUNTIFS('DATA ENVIOS'!$B$4:$B$2000,$A34,'DATA ENVIOS'!$A$4:$A$2000,Config!$B$4,'DATA ENVIOS'!$D$4:$D$2000,"Entregado")) -> 2 | D34: =IF($A34="","",COUNTIFS('DATA ENVIOS'!$B$4:$B$2000,$A34,'DATA ENVIOS'!$A$4:$A$2000,Config!$B$9,'DATA ENVIOS'!$D$4:$D$2000,"Entregado")) -> 0 | E34: =IF($A34="","",COUNTIFS('DATA ENVIOS'!$B$4:$B$2000,$A34,'DATA ENVIOS'!$A$4:$A$2000,Config!$B$10,'DATA ENVIOS'!$D$4:$D$2000,"Entregado")) -> 0 | F34: =IF($A34="","",SUMIFS('DATA RECOJOS'!$D$4:$D$201,'DATA RECOJOS'!$B$4:$B$201,$A34,'DATA RECOJOS'!$A$4:$A$201,Config!$B$9)) -> 0 | G34: =IF($A34="","",SUMIFS('DATA RECOJOS'!$D$4:$D$201,'DATA RECOJOS'!$B$4:$B$201,$A34,'DATA RECOJOS'!$A$4:$A$201,Config!$B$10)) -> 0 | H34: =IF($A34="","",$E34+$G34) -> 0 | I34: =IF($A34="","",IF($H34>0,"Leads ganados activos",IF(($D34+$F34)>0,"Leads ganados a dar seguimiento",IF($C34>0,"Lead ganado perdido","-")))) -> Lead ganado perdido
A35: =IF(Tiendas!$A17="","",Tiendas!$A17) -> Trends importaciones | B35: =IF($A35="","",Tiendas!$B17) -> SANDRA | C35: =IF($A35="","",COUNTIFS('DATA ENVIOS'!$B$4:$B$2000,$A35,'DATA ENVIOS'!$A$4:$A$2000,Config!$B$4,'DATA ENVIOS'!$D$4:$D$2000,"Entregado")) -> 10 | D35: =IF($A35="","",COUNTIFS('DATA ENVIOS'!$B$4:$B$2000,$A35,'DATA ENVIOS'!$A$4:$A$2000,Config!$B$9,'DATA ENVIOS'!$D$4:$D$2000,"Entregado")) -> 0 | E35: =IF($A35="","",COUNTIFS('DATA ENVIOS'!$B$4:$B$2000,$A35,'DATA ENVIOS'!$A$4:$A$2000,Config!$B$10,'DATA ENVIOS'!$D$4:$D$2000,"Entregado")) -> 0 | F35: =IF($A35="","",SUMIFS('DATA RECOJOS'!$D$4:$D$201,'DATA RECOJOS'!$B$4:$B$201,$A35,'DATA RECOJOS'!$A$4:$A$201,Config!$B$9)) -> 0 | G35: =IF($A35="","",SUMIFS('DATA RECOJOS'!$D$4:$D$201,'DATA RECOJOS'!$B$4:$B$201,$A35,'DATA RECOJOS'!$A$4:$A$201,Config!$B$10)) -> 0 | H35: =IF($A35="","",$E35+$G35) -> 0 | I35: =IF($A35="","",IF($H35>0,"Leads ganados activos",IF(($D35+$F35)>0,"Leads ganados a dar seguimiento",IF($C35>0,"Lead ganado perdido","-")))) -> Lead ganado perdido
A36: =IF(Tiendas!$A30="","",Tiendas!$A30) -> FABRU SHOP | B36: =IF($A36="","",Tiendas!$B30) -> CHRISTIAN | C36: =IF($A36="","",COUNTIFS('DATA ENVIOS'!$B$4:$B$2000,$A36,'DATA ENVIOS'!$A$4:$A$2000,Config!$B$4,'DATA ENVIOS'!$D$4:$D$2000,"Entregado")) -> 1 | D36: =IF($A36="","",COUNTIFS('DATA ENVIOS'!$B$4:$B$2000,$A36,'DATA ENVIOS'!$A$4:$A$2000,Config!$B$9,'DATA ENVIOS'!$D$4:$D$2000,"Entregado")) -> 0 | E36: =IF($A36="","",COUNTIFS('DATA ENVIOS'!$B$4:$B$2000,$A36,'DATA ENVIOS'!$A$4:$A$2000,Config!$B$10,'DATA ENVIOS'!$D$4:$D$2000,"Entregado")) -> 0 | F36: =IF($A36="","",SUMIFS('DATA RECOJOS'!$D$4:$D$201,'DATA RECOJOS'!$B$4:$B$201,$A36,'DATA RECOJOS'!$A$4:$A$201,Config!$B$9)) -> 0 | G36: =IF($A36="","",SUMIFS('DATA RECOJOS'!$D$4:$D$201,'DATA RECOJOS'!$B$4:$B$201,$A36,'DATA RECOJOS'!$A$4:$A$201,Config!$B$10)) -> 0 | H36: =IF($A36="","",$E36+$G36) -> 0 | I36: =IF($A36="","",IF($H36>0,"Leads ganados activos",IF(($D36+$F36)>0,"Leads ganados a dar seguimiento",IF($C36>0,"Lead ganado perdido","-")))) -> Lead ganado perdido
A37: =IF(Tiendas!$A42="","",Tiendas!$A42) -> Thialeshop Perú | B37: =IF($A37="","",Tiendas!$B42) -> SANDRA | C37: =IF($A37="","",COUNTIFS('DATA ENVIOS'!$B$4:$B$2000,$A37,'DATA ENVIOS'!$A$4:$A$2000,Config!$B$4,'DATA ENVIOS'!$D$4:$D$2000,"Entregado")) -> 11 | D37: =IF($A37="","",COUNTIFS('DATA ENVIOS'!$B$4:$B$2000,$A37,'DATA ENVIOS'!$A$4:$A$2000,Config!$B$9,'DATA ENVIOS'!$D$4:$D$2000,"Entregado")) -> 0 | E37: =IF($A37="","",COUNTIFS('DATA ENVIOS'!$B$4:$B$2000,$A37,'DATA ENVIOS'!$A$4:$A$2000,Config!$B$10,'DATA ENVIOS'!$D$4:$D$2000,"Entregado")) -> 0 | F37: =IF($A37="","",SUMIFS('DATA RECOJOS'!$D$4:$D$201,'DATA RECOJOS'!$B$4:$B$201,$A37,'DATA RECOJOS'!$A$4:$A$201,Config!$B$9)) -> 0 | G37: =IF($A37="","",SUMIFS('DATA RECOJOS'!$D$4:$D$201,'DATA RECOJOS'!$B$4:$B$201,$A37,'DATA RECOJOS'!$A$4:$A$201,Config!$B$10)) -> 0 | H37: =IF($A37="","",$E37+$G37) -> 0 | I37: =IF($A37="","",IF($H37>0,"Leads ganados activos",IF(($D37+$F37)>0,"Leads ganados a dar seguimiento",IF($C37>0,"Lead ganado perdido","-")))) -> Lead ganado perdido
A38: =IF(Tiendas!$A52="","",Tiendas!$A52) -> Reyshop Perú sac | B38: =IF($A38="","",Tiendas!$B52) -> SEBASTIAN | C38: =IF($A38="","",COUNTIFS('DATA ENVIOS'!$B$4:$B$2000,$A38,'DATA ENVIOS'!$A$4:$A$2000,Config!$B$4,'DATA ENVIOS'!$D$4:$D$2000,"Entregado")) -> 13 | D38: =IF($A38="","",COUNTIFS('DATA ENVIOS'!$B$4:$B$2000,$A38,'DATA ENVIOS'!$A$4:$A$2000,Config!$B$9,'DATA ENVIOS'!$D$4:$D$2000,"Entregado")) -> 0 | E38: =IF($A38="","",COUNTIFS('DATA ENVIOS'!$B$4:$B$2000,$A38,'DATA ENVIOS'!$A$4:$A$2000,Config!$B$10,'DATA ENVIOS'!$D$4:$D$2000,"Entregado")) -> 0 | F38: =IF($A38="","",SUMIFS('DATA RECOJOS'!$D$4:$D$201,'DATA RECOJOS'!$B$4:$B$201,$A38,'DATA RECOJOS'!$A$4:$A$201,Config!$B$9)) -> 0 | G38: =IF($A38="","",SUMIFS('DATA RECOJOS'!$D$4:$D$201,'DATA RECOJOS'!$B$4:$B$201,$A38,'DATA RECOJOS'!$A$4:$A$201,Config!$B$10)) -> 0 | H38: =IF($A38="","",$E38+$G38) -> 0 | I38: =IF($A38="","",IF($H38>0,"Leads ganados activos",IF(($D38+$F38)>0,"Leads ganados a dar seguimiento",IF($C38>0,"Lead ganado perdido","-")))) -> Lead ganado perdido
A39: =IF(Tiendas!$A15="","",Tiendas!$A15) -> ALOANKA IMPORT | B39: =IF($A39="","",Tiendas!$B15) -> SANDRA | C39: =IF($A39="","",COUNTIFS('DATA ENVIOS'!$B$4:$B$2000,$A39,'DATA ENVIOS'!$A$4:$A$2000,Config!$B$4,'DATA ENVIOS'!$D$4:$D$2000,"Entregado")) -> 2 | D39: =IF($A39="","",COUNTIFS('DATA ENVIOS'!$B$4:$B$2000,$A39,'DATA ENVIOS'!$A$4:$A$2000,Config!$B$9,'DATA ENVIOS'!$D$4:$D$2000,"Entregado")) -> 0 | E39: =IF($A39="","",COUNTIFS('DATA ENVIOS'!$B$4:$B$2000,$A39,'DATA ENVIOS'!$A$4:$A$2000,Config!$B$10,'DATA ENVIOS'!$D$4:$D$2000,"Entregado")) -> 0 | F39: =IF($A39="","",SUMIFS('DATA RECOJOS'!$D$4:$D$201,'DATA RECOJOS'!$B$4:$B$201,$A39,'DATA RECOJOS'!$A$4:$A$201,Config!$B$9)) -> 0 | G39: =IF($A39="","",SUMIFS('DATA RECOJOS'!$D$4:$D$201,'DATA RECOJOS'!$B$4:$B$201,$A39,'DATA RECOJOS'!$A$4:$A$201,Config!$B$10)) -> 0 | H39: =IF($A39="","",$E39+$G39) -> 0 | I39: =IF($A39="","",IF($H39>0,"Leads ganados activos",IF(($D39+$F39)>0,"Leads ganados a dar seguimiento",IF($C39>0,"Lead ganado perdido","-")))) -> Lead ganado perdido
A40: =IF(Tiendas!$A19="","",Tiendas!$A19) -> Importa Pe | B40: =IF($A40="","",Tiendas!$B19) -> SEBASTIAN | C40: =IF($A40="","",COUNTIFS('DATA ENVIOS'!$B$4:$B$2000,$A40,'DATA ENVIOS'!$A$4:$A$2000,Config!$B$4,'DATA ENVIOS'!$D$4:$D$2000,"Entregado")) -> 3 | D40: =IF($A40="","",COUNTIFS('DATA ENVIOS'!$B$4:$B$2000,$A40,'DATA ENVIOS'!$A$4:$A$2000,Config!$B$9,'DATA ENVIOS'!$D$4:$D$2000,"Entregado")) -> 0 | E40: =IF($A40="","",COUNTIFS('DATA ENVIOS'!$B$4:$B$2000,$A40,'DATA ENVIOS'!$A$4:$A$2000,Config!$B$10,'DATA ENVIOS'!$D$4:$D$2000,"Entregado")) -> 0 | F40: =IF($A40="","",SUMIFS('DATA RECOJOS'!$D$4:$D$201,'DATA RECOJOS'!$B$4:$B$201,$A40,'DATA RECOJOS'!$A$4:$A$201,Config!$B$9)) -> 0 | G40: =IF($A40="","",SUMIFS('DATA RECOJOS'!$D$4:$D$201,'DATA RECOJOS'!$B$4:$B$201,$A40,'DATA RECOJOS'!$A$4:$A$201,Config!$B$10)) -> 0 | H40: =IF($A40="","",$E40+$G40) -> 0 | I40: =IF($A40="","",IF($H40>0,"Leads ganados activos",IF(($D40+$F40)>0,"Leads ganados a dar seguimiento",IF($C40>0,"Lead ganado perdido","-")))) -> Lead ganado perdido
A41: =IF(Tiendas!$A21="","",Tiendas!$A21) -> PATRICIA NUSKIN | B41: =IF($A41="","",Tiendas!$B21) -> SEBASTIAN | C41: =IF($A41="","",COUNTIFS('DATA ENVIOS'!$B$4:$B$2000,$A41,'DATA ENVIOS'!$A$4:$A$2000,Config!$B$4,'DATA ENVIOS'!$D$4:$D$2000,"Entregado")) -> 12 | D41: =IF($A41="","",COUNTIFS('DATA ENVIOS'!$B$4:$B$2000,$A41,'DATA ENVIOS'!$A$4:$A$2000,Config!$B$9,'DATA ENVIOS'!$D$4:$D$2000,"Entregado")) -> 0 | E41: =IF($A41="","",COUNTIFS('DATA ENVIOS'!$B$4:$B$2000,$A41,'DATA ENVIOS'!$A$4:$A$2000,Config!$B$10,'DATA ENVIOS'!$D$4:$D$2000,"Entregado")) -> 0 | F41: =IF($A41="","",SUMIFS('DATA RECOJOS'!$D$4:$D$201,'DATA RECOJOS'!$B$4:$B$201,$A41,'DATA RECOJOS'!$A$4:$A$201,Config!$B$9)) -> 0 | G41: =IF($A41="","",SUMIFS('DATA RECOJOS'!$D$4:$D$201,'DATA RECOJOS'!$B$4:$B$201,$A41,'DATA RECOJOS'!$A$4:$A$201,Config!$B$10)) -> 0 | H41: =IF($A41="","",$E41+$G41) -> 0 | I41: =IF($A41="","",IF($H41>0,"Leads ganados activos",IF(($D41+$F41)>0,"Leads ganados a dar seguimiento",IF($C41>0,"Lead ganado perdido","-")))) -> Lead ganado perdido
...

Sheet INFO TIENDA
A1: Vista_Tienda — resumen del mes (envíos + recojos)
A3: Selecciona tienda | B3: {=IFERROR(INDEX(Helper_Vendedor!$A$4:$A$177,MATCH(1,Helper_Vendedor!$D$4:$D$177,0)),"-")} -> AVEFENIX3107
A5: Vendedor | B5: =IF($B$3="","",VLOOKUP($B$3,Tiendas!$A$4:$K$176,2,FALSE)) -> JORDAN
A6: Fulfillment | B6: =IF($B$3="","",VLOOKUP($B$3,Tiendas!$A$4:$K$176,9,FALSE)) -> Si
A7: Fecha ingreso lead | B7: =IF($B$3="","",VLOOKUP($B$3,Tiendas!$A$4:$K$176,3,FALSE)) -> 46027
A8: Fecha registro lead | B8: =IF($B$3="","",VLOOKUP($B$3,Tiendas!$A$4:$K$176,4,FALSE)) -> 46028
A9: Fecha Lead Ganado | B9: =IF($B$3="","",VLOOKUP($B$3,Tiendas!$A$4:$K$176,5,FALSE)) -> 46032
A10: Días Lead→Ganado | B10: =IF($B$3="","",VLOOKUP($B$3,Tiendas!$A$4:$K$176,8,FALSE)) -> 5
A11: Lead ganado en periodo? | B11: =IF($B$3="","",VLOOKUP($B$3,Tiendas!$A$4:$K$176,10,FALSE)) -> Sí
A13: Resumen del periodo
A14: Periodo | B14: =Config!$B$4 -> 46023 | D14: Envios | G14: Recojos
D15: N° entregados | E15: =IF($B$3="","",COUNTIFS('DATA ENVIOS'!$B$4:$B$2000,$B$3,'DATA ENVIOS'!$D$4:$D$2000,"Entregado",'DATA ENVIOS'!$A$4:$A$2000,Config!$B$4)) -> 292 | G15: Recojos cobrados (veces) | H15: =IF($B$3="","",SUMIFS('DATA RECOJOS'!$D$4:$D$201,'DATA RECOJOS'!$B$4:$B$201,$B$3,'DATA RECOJOS'!$A$4:$A$201,Config!$B$4,'DATA RECOJOS'!$C$4:$C$201,"1 pedido (cobra S/8)")) -> 0
D16: N° rechazados | E16: =IF($B$3="","",COUNTIFS('DATA ENVIOS'!$B$4:$B$2000,$B$3,'DATA ENVIOS'!$D$4:$D$2000,"Rechazado",'DATA ENVIOS'!$A$4:$A$2000,Config!$B$4)) -> 1 | G16: Recojos gratis (veces) | H16: =IF($B$3="","",SUMIFS('DATA RECOJOS'!$D$4:$D$201,'DATA RECOJOS'!$B$4:$B$201,$B$3,'DATA RECOJOS'!$A$4:$A$201,Config!$B$4,'DATA RECOJOS'!$C$4:$C$201,"2+ entregados (gratis)")) -> 0
D17: Ingreso envíos (S/) | E17: =IF($B$3="","",SUMIFS('DATA ENVIOS'!$H$4:$H$2000,'DATA ENVIOS'!$B$4:$B$2000,$B$3,'DATA ENVIOS'!$A$4:$A$2000,Config!$B$4)) -> 2894.9153 | G17: Ingreso recojos (S/) | H17: =IF($B$3="","",SUMIFS('DATA RECOJOS'!$G$4:$G$201,'DATA RECOJOS'!$B$4:$B$201,$B$3,'DATA RECOJOS'!$A$4:$A$201,Config!$B$4)) -> 0
D18: Costo envíos (S/) | E18: =IF($B$3="","",SUMIFS('DATA ENVIOS'!$I$4:$I$2000,'DATA ENVIOS'!$B$4:$B$2000,$B$3,'DATA ENVIOS'!$A$4:$A$2000,Config!$B$4)) -> 1459.5 | G18: Costo recojos (S/) | H18: =IF($B$3="","",SUMIFS('DATA RECOJOS'!$H$4:$H$201,'DATA RECOJOS'!$B$4:$B$201,$B$3,'DATA RECOJOS'!$A$4:$A$201,Config!$B$4)) -> 0
D19: Margen envíos (S/) | E19: =IF($B$3="","",E17-E18) -> 1435.4153
A21: TOTAL OPERATIVO | D21: Ingreso total (S/) | E21: =E17+H17 -> 2894.9153 | F21: Costo total (S/) | G21: =E18+H18 -> 1459.5 | H21: Margen total (S/)
H22: =E21-G21 -> 1435.4153

Sheet Tiendas
A1: DATA DE LEADS GANADOS
A3: Nombre tienda | B3: Vendedor | C3: Fecha ingreso lead | D3: Fecha registro lead | E3: Fecha Lead Ganado | F3: Días Lead→Registro | G3: Días Registro→Ganado | H3: Días Lead→Ganado | I3: Fulfillment | J3: Lead ganado en periodo? | K3: Notas | L3: Cantidad de envíos | M3: Origen lead | N3: Distrito (lead ganado) | O3: Nivel vendedor (periodo) | P3: Tienda_ID (auto) | Q3: Anulados Fulfillment | R3: Ingreso anulados fulfillment (S/)
A4: Forever20 | B4: ALEXIS | C4: 46045 | D4: 46045 | E4: 46046 | F4: =IF(OR(C4="",D4=""),"",D4-C4) -> 0 | G4: =IF(OR(D4="",E4=""),"",E4-D4) -> 1 | H4: =IF(OR(C4="",E4=""),"",E4-C4) -> 1 | I4: No | J4: =IF(E4="","",IF(AND(E4>=Config!$B$5,E4<=Config!$B$6),"Sí","No")) -> Sí | L4: =IF($A4="","",COUNTIFS('DATA ENVIOS'!$B$4:$B$2000,$A4,'DATA ENVIOS'!$A$4:$A$2000,Config!$B$4)) -> 13 | M4: Entrante | N4: Santa Anita | R4: =IF($Q4="",0,$Q4*2) -> 0
A5: Seralta | B5: ALEXIS | C5: 46029 | D5: 46029 | E5: 46030 | F5: =IF(OR(C5="",D5=""),"",D5-C5) -> 0 | G5: =IF(OR(D5="",E5=""),"",E5-D5) -> 1 | H5: =IF(OR(C5="",E5=""),"",E5-C5) -> 1 | I5: No | J5: =IF(E5="","",IF(AND(E5>=Config!$B$5,E5<=Config!$B$6),"Sí","No")) -> Sí | L5: =IF($A5="","",COUNTIFS('DATA ENVIOS'!$B$4:$B$2000,$A5,'DATA ENVIOS'!$A$4:$A$2000,Config!$B$4)) -> 66 | M5: Entrante | N5: San Martín de Porres | R5: =IF($Q5="",0,$Q5*2) -> 0
A6: FELIPE AMORIN CABALLERO | B6: CHRISTIAN | C6: 46038 | D6: 46038 | E6: 46039 | F6: =IF(OR(C6="",D6=""),"",D6-C6) -> 0 | G6: =IF(OR(D6="",E6=""),"",E6-D6) -> 1 | H6: =IF(OR(C6="",E6=""),"",E6-C6) -> 1 | I6: No | J6: =IF(E6="","",IF(AND(E6>=Config!$B$5,E6<=Config!$B$6),"Sí","No")) -> Sí | L6: =IF($A6="","",COUNTIFS('DATA ENVIOS'!$B$4:$B$2000,$A6,'DATA ENVIOS'!$A$4:$A$2000,Config!$B$4)) -> 1 | M6: Entrante | N6: Villa María del Triunfo | R6: =IF($Q6="",0,$Q6*2) -> 0
A7: Vrillita | B7: CHRISTIAN | C7: 46046 | D7: 46046 | E7: 46047 | F7: =IF(OR(C7="",D7=""),"",D7-C7) -> 0 | G7: =IF(OR(D7="",E7=""),"",E7-D7) -> 1 | H7: =IF(OR(C7="",E7=""),"",E7-C7) -> 1 | I7: No | J7: =IF(E7="","",IF(AND(E7>=Config!$B$5,E7<=Config!$B$6),"Sí","No")) -> Sí | L7: =IF($A7="","",COUNTIFS('DATA ENVIOS'!$B$4:$B$2000,$A7,'DATA ENVIOS'!$A$4:$A$2000,Config!$B$4)) -> 1 | M7: Entrante | N7: Magdalena del Mar | R7: =IF($Q7="",0,$Q7*2) -> 0
A8: Tiens By Lucy | B8: CHRISTIAN | C8: 46051 | D8: 46051 | E8: 46052 | F8: =IF(OR(C8="",D8=""),"",D8-C8) -> 0 | G8: =IF(OR(D8="",E8=""),"",E8-D8) -> 1 | H8: =IF(OR(C8="",E8=""),"",E8-C8) -> 1 | I8: No | J8: =IF(E8="","",IF(AND(E8>=Config!$B$5,E8<=Config!$B$6),"Sí","No")) -> Sí | L8: =IF($A8="","",COUNTIFS('DATA ENVIOS'!$B$4:$B$2000,$A8,'DATA ENVIOS'!$A$4:$A$2000,Config!$B$4)) -> 1 | M8: Entrante | N8: San Martín de Porres | R8: =IF($Q8="",0,$Q8*2) -> 0
A9: speechless_peru | B9: CHRISTIAN | C9: 46051 | D9: 46051 | E9: 46052 | F9: =IF(OR(C9="",D9=""),"",D9-C9) -> 0 | G9: =IF(OR(D9="",E9=""),"",E9-D9) -> 1 | H9: =IF(OR(C9="",E9=""),"",E9-C9) -> 1 | I9: No | J9: =IF(E9="","",IF(AND(E9>=Config!$B$5,E9<=Config!$B$6),"Sí","No")) -> Sí | L9: =IF($A9="","",COUNTIFS('DATA ENVIOS'!$B$4:$B$2000,$A9,'DATA ENVIOS'!$A$4:$A$2000,Config!$B$4)) -> 2 | M9: Entrante | N9: El Agustino | R9: =IF($Q9="",0,$Q9*2) -> 0
A10: Fame shop | B10: CHRISTIAN | C10: 46031 | D10: 46031 | E10: 46032 | F10: =IF(OR(C10="",D10=""),"",D10-C10) -> 0 | G10: =IF(OR(D10="",E10=""),"",E10-D10) -> 1 | H10: =IF(OR(C10="",E10=""),"",E10-C10) -> 1 | I10: No | J10: =IF(E10="","",IF(AND(E10>=Config!$B$5,E10<=Config!$B$6),"Sí","No")) -> Sí | L10: =IF($A10="","",COUNTIFS('DATA ENVIOS'!$B$4:$B$2000,$A10,'DATA ENVIOS'!$A$4:$A$2000,Config!$B$4)) -> 9 | M10: Entrante | N10: San Borja | R10: =IF($Q10="",0,$Q10*2) -> 0
A11: Joyful Shop | B11: CHRISTIAN | C11: 46044 | D11: 46044 | E11: 46045 | F11: =IF(OR(C11="",D11=""),"",D11-C11) -> 0 | G11: =IF(OR(D11="",E11=""),"",E11-D11) -> 1 | H11: =IF(OR(C11="",E11=""),"",E11-C11) -> 1 | I11: No | J11: =IF(E11="","",IF(AND(E11>=Config!$B$5,E11<=Config!$B$6),"Sí","No")) -> Sí | L11: =IF($A11="","",COUNTIFS('DATA ENVIOS'!$B$4:$B$2000,$A11,'DATA ENVIOS'!$A$4:$A$2000,Config!$B$4)) -> 21 | M11: Entrante | N11: Los Olivos | R11: =IF($Q11="",0,$Q11*2) -> 0
A12: Industrias Osorio | B12: JORDAN | C12: 46036 | D12: 46036 | E12: 46037 | F12: =IF(OR(C12="",D12=""),"",D12-C12) -> 0 | G12: =IF(OR(D12="",E12=""),"",E12-D12) -> 1 | H12: =IF(OR(C12="",E12=""),"",E12-C12) -> 1 | I12: No | J12: =IF(E12="","",IF(AND(E12>=Config!$B$5,E12<=Config!$B$6),"Sí","No")) -> Sí | L12: =IF($A12="","",COUNTIFS('DATA ENVIOS'!$B$4:$B$2000,$A12,'DATA ENVIOS'!$A$4:$A$2000,Config!$B$4)) -> 1 | M12: Entrante | N12: Cercado de Lima | R12: =IF($Q12="",0,$Q12*2) -> 0
A13: NAYTEL STORE | B13: JORDAN | C13: 46044 | D13: 46044 | E13: 46045 | F13: =IF(OR(C13="",D13=""),"",D13-C13) -> 0 | G13: =IF(OR(D13="",E13=""),"",E13-D13) -> 1 | H13: =IF(OR(C13="",E13=""),"",E13-C13) -> 1 | I13: No | J13: =IF(E13="","",IF(AND(E13>=Config!$B$5,E13<=Config!$B$6),"Sí","No")) -> Sí | L13: =IF($A13="","",COUNTIFS('DATA ENVIOS'!$B$4:$B$2000,$A13,'DATA ENVIOS'!$A$4:$A$2000,Config!$B$4)) -> 1 | M13: Entrante | N13: Carabayllo | R13: =IF($Q13="",0,$Q13*2) -> 0
A14: Lune Atelier | B14: JORDAN | C14: 46043 | D14: 46043 | E14: 46044 | F14: =IF(OR(C14="",D14=""),"",D14-C14) -> 0 | G14: =IF(OR(D14="",E14=""),"",E14-D14) -> 1 | H14: =IF(OR(C14="",E14=""),"",E14-C14) -> 1 | I14: No | J14: =IF(E14="","",IF(AND(E14>=Config!$B$5,E14<=Config!$B$6),"Sí","No")) -> Sí | L14: =IF($A14="","",COUNTIFS('DATA ENVIOS'!$B$4:$B$2000,$A14,'DATA ENVIOS'!$A$4:$A$2000,Config!$B$4)) -> 4 | M14: Entrante | N14: San Martín de Porres | R14: =IF($Q14="",0,$Q14*2) -> 0
A15: ALOANKA IMPORT | B15: SANDRA | C15: 46034 | D15: 46034 | E15: 46035 | F15: =IF(OR(C15="",D15=""),"",D15-C15) -> 0 | G15: =IF(OR(D15="",E15=""),"",E15-D15) -> 1 | H15: =IF(OR(C15="",E15=""),"",E15-C15) -> 1 | I15: No | J15: =IF(E15="","",IF(AND(E15>=Config!$B$5,E15<=Config!$B$6),"Sí","No")) -> Sí | L15: =IF($A15="","",COUNTIFS('DATA ENVIOS'!$B$4:$B$2000,$A15,'DATA ENVIOS'!$A$4:$A$2000,Config!$B$4)) -> 2 | M15: Entrante | N15: Breña | R15: =IF($Q15="",0,$Q15*2) -> 0
... A34: Maia collection | B34: SANDRA | C34: 46024 | D34: 46024 | E34: 46027 | F34: =IF(OR(C34="",D34=""),"",D34-C34) -> 0 | G34: =IF(OR(D34="",E34=""),"",E34-D34) -> 3 | H34: =IF(OR(C34="",E34=""),"",E34-C34) -> 3 | I34: No | J34: =IF(E34="","",IF(AND(E34>=Config!$B$5,E34<=Config!$B$6),"Sí","No")) -> Sí | L34: =IF($A34="","",COUNTIFS('DATA ENVIOS'!$B$4:$B$2000,$A34,'DATA ENVIOS'!$A$4:$A$2000,Config!$B$4)) -> 23 | M34: Entrante | N34: El Agustino | R34: =IF($Q34="",0,$Q34*2) -> 0
